Workbook

Sheet Sheet1
A1: label ID | B1: CROSS | C1: LINE | D1: PLANT_ID | E1: Rhizomes | F1: Weight (g DW) | G1: Length(cm) | H1: ProjArea(cm2) | I1: SurfArea(cm2) | J1: AvgDiam(mm) | K1: 0<.L.<=0.0500000 | L1: 0.0500000<.L.<=0.1000000 | M1: 0.1000000<.L.<=0.1500000 | N1: 0.1500000<.L.<=0.2000000 | O1: 0.2000000<.L.<=0.2500000 | P1: 0.2500000<.L.<=0.3000000 | Q1: 0.3000000<.L.<=0.3500000 | R1: 0.3500000<.L.<=0.4000000 | S1: 0.4000000<.L.<=0.4500000 | T1: 0.4500000<.L.<=0.5000000 | U1: 0.5000000<.L.<=0.5500000 | V1: 0.5500000<.L.<=0.6000000 | W1: 0.6000000<.L.<=0.6500000 | X1: 0.6500000<.L.<=0.7000000 | Y1: 0.7000000<.L.<=0.7500000 | Z1: 0.7500000<.L.<=0.8000000 | AA1: 0.8000000<.L.<=0.8500000 | AB1: 0.8500000<.L.<=0.9000000 | AC1: 0.9000000<.L.<=0.9500000 | AD1: 0.9500000<.L.<=1.0000000 | AE1: 1.0000000<.L.<=1.0500000 | AF1: 1.0500000<.L.<=1.1000000 | AG1: 1.1000000<.L.<=1.1500000 | AH1: 1.1500000<.L.<=1.2000000 | AI1: 1.2000000<.L.<=1.2500000 | AJ1: 1.2500000<.L.<=1.3000000 | AK1: 1.3000000<.L.<=1.3500000 | AL1: 1.3500000<.L.<=1.4000000 | AM1: 1.4000000<.L.<=1.4500000 | AN1: 1.4500000<.L.<=1.5000000 | AO1: 1.5000000<.L.<=1.5500000 | AP1: 1.5500000<.L.<=1.6000000 | AQ1: 1.6000000<.L.<=1.6500000 | AR1: 1.6500000<.L.<=1.7000000 | AS1: 1.7000000<.L.<=1.7500000 | AT1: 1.7500000<.L.<=1.8000000 | AU1: 1.8000000<.L.<=1.8500000 | AV1: 1.8500000<.L.<=1.9000000 | AW1: 1.9000000<.L.<=1.9500000 | AX1: 1.9500000<.L.<=2.0000000 | AY1: 2.0000000<.L.<=2.0500000 | AZ1: 2.0500000<.L.<=2.1000000 | BA1: 2.1000000<.L.<=2.1500000 | BB1: 2.1500000<.L.<=2.2000000 | BC1: 2.2000000<.L.<=2.2500000 | BD1: 2.2500000<.L.<=2.3000000 | BE1: 2.3000000<.L.<=2.3500000 | BF1: 2.3500000<.L.<=2.4000000 | BG1: 2.4000000<.L.<=2.4500000 | BH1: 2.4500000<.L.<=2.5000000 | BI1: 2.5000000<.L.<=2.5500000 | BJ1: 2.5500000<.L.<=2.6000000 | BK1: 2.6000000<.L.<=2.6500000 | BL1: 2.6500000<.L.<=2.7000000 | BM1: 2.7000000<.L.<=2.7500000 | BN1: 2.7500000<.L.<=2.8000000 | BO1: 2.8000000<.L.<=2.8500000 | BP1: 2.8500000<.L.<=2.9000000 | BQ1: 2.9000000<.L.<=2.9500000 | BR1: 2.9500000<.L.<=3.0000000 | BS1: 3.0000000<.L.<=3.0500000 | BT1: 3.0500000<.L.<=3.1000000 | BU1: 3.1000000<.L.<=3.1500000 | BV1: 3.1500000<.L.<=3.2000000 | BW1: 3.2000000<.L.<=3.2500000 | BX1: 3.2500000<.L.<=3.3000000 | BY1: 3.3000000<.L.<=3.3500000 | BZ1: 3.3500000<.L.<=3.4000000 | CA1: 3.4000000<.L.<=3.4500000 | CB1: 3.4500000<.L.<=3.5000000 | CC1: 3.5000000<.L.<=3.5500000 | CD1: 3.5500000<.L.<=3.6000000 | CE1: 3.6000000<.L.<=3.6500000 | CF1: 3.6500000<.L.<=3.7000000 | CG1: 3.7000000<.L.<=3.7500000 | CH1: 3.7500000<.L.<=3.8000000 | CI1: 3.8000000<.L.<=3.8500000 | CJ1: 3.8500000<.L.<=3.9000000 | CK1: 3.9000000<.L.<=3.9500000 | CL1: 3.9500000<.L.<=4.0000000 | CM1: .L.>4.0000000 | CN1: 0<.SA.<=0.0500000 | CO1: 0.0500000<.SA.<=0.1000000 | CP1: 0.1000000<.SA.<=0.1500000 | CQ1: 0.1500000<.SA.<=0.2000000 | CR1: 0.2000000<.SA.<=0.2500000 | CS1: 0.2500000<.SA.<=0.3000000 | CT1: 0.3000000<.SA.<=0.3500000 | CU1: 0.3500000<.SA.<=0.4000000 | CV1: 0.4000000<.SA.<=0.4500000 | CW1: 0.4500000<.SA.<=0.5000000 | CX1: 0.5000000<.SA.<=0.5500000 | CY1: 0.5500000<.SA.<=0.6000000 | CZ1: 0.6000000<.SA.<=0.6500000 | DA1: 0.6500000<.SA.<=0.7000000 | DB1: 0.7000000<.SA.<=0.7500000 | DC1: 0.7500000<.SA.<=0.8000000 | DD1: 0.8000000<.SA.<=0.8500000 | DE1: 0.8500000<.SA.<=0.9000000 | DF1: 0.9000000<.SA.<=0.9500000 | DG1: 0.9500000<.SA.<=1.0000000 | DH1: 1.0000000<.SA.<=1.0500000 | DI1: 1.0500000<.SA.<=1.1000000 | DJ1: 1.1000000<.SA.<=1.1500000 | DK1: 1.1500000<.SA.<=1.2000000 | DL1: 1.2000000<.SA.<=1.2500000 | DM1: 1.2500000<.SA.<=1.3000000 | DN1: 1.3000000<.SA.<=1.3500000 | DO1: 1.3500000<.SA.<=1.4000000 | DP1: 1.4000000<.SA.<=1.4500000 | DQ1: 1.4500000<.SA.<=1.5000000 | DR1: 1.5000000<.SA.<=1.5500000 | DS1: 1.5500000<.SA.<=1.6000000 | DT1: 1.6000000<.SA.<=1.6500000 | DU1: 1.6500000<.SA.<=1.7000000 | DV1: 1.7000000<.SA.<=1.7500000 | DW1: 1.7500000<.SA.<=1.8000000 | DX1: 1.8000000<.SA.<=1.8500000 | DY1: 1.8500000<.SA.<=1.9000000 | DZ1: 1.9000000<.SA.<=1.9500000 | EA1: 1.9500000<.SA.<=2.0000000 | EB1: 2.0000000<.SA.<=2.0500000 | EC1: 2.0500000<.SA.<=2.1000000 | ED1: 2.1000000<.SA.<=2.1500000 | EE1: 2.1500000<.SA.<=2.2000000 | EF1: 2.2000000<.SA.<=2.2500000 | EG1: 2.2500000<.SA.<=2.3000000 | EH1: 2.3000000<.SA.<=2.3500000 | EI1: 2.3500000<.SA.<=2.4000000 | EJ1: 2.4000000<.SA.<=2.4500000 | EK1: 2.4500000<.SA.<=2.5000000 | EL1: 2.5000000<.SA.<=2.5500000 | EM1: 2.5500000<.SA.<=2.6000000 | EN1: 2.6000000<.SA.<=2.6500000 | EO1: 2.6500000<.SA.<=2.7000000 | EP1: 2.7000000<.SA.<=2.7500000 | EQ1: 2.7500000<.SA.<=2.8000000 | ER1: 2.8000000<.SA.<=2.8500000 | ES1: 2.8500000<.SA.<=2.9000000 | ET1: 2.9000000<.SA.<=2.9500000 | EU1: 2.9500000<.SA.<=3.0000000 | EV1: 3.0000000<.SA.<=3.0500000 | EW1: 3.0500000<.SA.<=3.1000000 | EX1: 3.1000000<.SA.<=3.1500000 | EY1: 3.1500000<.SA.<=3.2000000 | EZ1: 3.2000000<.SA.<=3.2500000 | FA1: 3.2500000<.SA.<=3.3000000 | FB1: 3.3000000<.SA.<=3.3500000 | FC1: 3.3500000<.SA.<=3.4000000 | FD1: 3.4000000<.SA.<=3.4500000 | FE1: 3.4500000<.SA.<=3.5000000 | FF1: 3.5000000<.SA.<=3.5500000 | FG1: 3.5500000<.SA.<=3.6000000 | FH1: 3.6000000<.SA.<=3.6500000 | FI1: 3.6500000<.SA.<=3.7000000 | FJ1: 3.7000000<.SA.<=3.7500000 | FK1: 3.7500000<.SA.<=3.8000000 | FL1: 3.8000000<.SA.<=3.8500000 | FM1: 3.8500000<.SA.<=3.9000000 | FN1: 3.9000000<.SA.<=3.9500000 | FO1: 3.9500000<.SA.<=4.0000000 | FP1: .SA.>4.0000000
A2: N1001 | B2: VWAD | C2: 88 | D2: VWAD.88.4 | G2: 3797.3749 | H2: 231.6935 | I2: 727.8866 | J2: 0.6193875 | K2: 0 | L2: 9.1865 | M2: 28.206 | N2: 435.8132 | O2: 561.2879 | P2: 466.9262 | Q2: 632.9216 | R2: 282.6667 | S2: 181.5745 | T2: 134.2252 | U2: 160.9919 | V2: 61.5662 | W2: 88.9034 | X2: 51.0475 | Y2: 33.2879 | Z2: 40.4841 | AA2: 45.0474 | AB2: 37.8467 | AC2: 32.5079 | AD2: 36.5726 | AE2: 22.8441 | AF2: 32.6888 | AG2: 11.9547 | AH2: 29.1416 | AI2: 42.3222 | AJ2: 19.8208 | AK2: 35.5442 | AL2: 19.3675 | AM2: 29.2769 | AN2: 34.9475 | AO2: 29.669 | AP2: 26.6725 | AQ2: 28.3547 | AR2: 20.4432 | AS2: 14.7104 | AT2: 19.4369 | AU2: 12.8299 | AV2: 6.8734 | AW2: 7.0829 | AX2: 7.4851 | AY2: 5.2436 | AZ2: 3.9816 | BA2: 1.8746 | BB2: 3.0167 | BC2: 1.5371 | BD2: 0.9027 | BE2: 1.1257 | BF2: 0.2285 | BG2: 0.7897 | BH2: 0.4379 | BI2: 0.2337 | BJ2: 0.3444 | BK2: 0.3198 | BL2: 0.2178 | BM2: 0.4721 | BN2: 0.2911 | BO2: 0.8428 | BP2: 0.1961 | BQ2: 0.0354 | BR2: 0.1793 | BS2: 0.0269 | BT2: 0.0201 | BU2: 0.2788 | BV2: 0.6077 | BW2: 0.0285 | BX2: 0.0497 | BY2: 0.0639 | BZ2: 0.0396 | CA2: 0.0201 | CB2: 0.0555 | CC2: 0.0397 | CD2: 0.0576 | CE2: 0.046 | CF2: 0.1349 | CG2: 0.0798 | CH2: 0.0069 | CI2: 0.1808 | CJ2: 0 | CK2: 0 | CL2: 0 | CM2: 0 | CN2: 0 | CO2: 0.252 | CP2: 1.1514 | CQ2: 24.9174 | CR2: 39.7354 | CS2: 39.144 | CT2: 63.5305 | CU2: 33.5744 | CV2: 24.1877 | CW2: 19.6927 | CX2: 26.7144 | CY2: 11.1725 | CZ2: 17.4078 | DA2: 11.0255 | DB2: 7.5625 | DC2: 9.7964 | DD2: 11.6282 | DE2: 10.4622 | DF2: 9.4415 | DG2: 11.2259 | DH2: 7.3261 | DI2: 11.0807 | DJ2: 4.2458 | DK2: 10.6972 | DL2: 16.3921 | DM2: 7.9314 | DN2: 14.8284 | DO2: 8.3846 | DP2: 13.0421 | DQ2: 16.2012 | DR2: 14.2895 | DS2: 13.1147 | DT2: 14.4447 | DU2: 10.7845 | DV2: 7.9602 | DW2: 10.7846 | DX2: 7.3653 | DY2: 4.0607 | DZ2: 4.2724 | EA2: 4.6494 | EB2: 3.3408 | EC2: 2.6091 | ED2: 1.2479 | EE2: 2.0582 | EF2: 1.0785 | EG2: 0.6467 | EH2: 0.8202 | EI2: 0.1703 | EJ2: 0.5989 | EK2: 0.3413 | EL2: 0.185 | EM2: 0.279 | EN2: 0.265 | EO2: 0.1819 | EP2: 0.4039 | EQ2: 0.2545 | ER2: 0.7503 | ES2: 0.1768 | ET2: 0.0326 | EU2: 0.1678 | EV2: 0.0257 | EW2: 0.0195 | EX2: 0.2745 | EY2: 0.6074 | EZ2: 0.0291 | FA2: 0.0509 | FB2: 0.0667 | FC2: 0.042 | FD2: 0.0216 | FE2: 0.0605 | FF2: 0.044 | FG2: 0.0648 | FH2: 0.0525 | FI2: 0.156 | FJ2: 0.0932 | FK2: 0.0081 | FL2: 0.2172 | FM2: 0 | FN2: 0 | FO2: 0 | FP2: 0
A3: N1002 | B3: ADVW | C3: 209 | D3: ADVW.209.4 | E3: =VLOOKUP(A3,[1]RHIZOMES!$A$1:$B$1048576,2,0) -> #N/A | F3: =VLOOKUP(A3,[1]ROOT!$A$1:$C$1048576,3,0) -> #N/A | G3: 2145.3141 | H3: 127.7677 | I3: 401.3938 | J3: 0.58986667 | K3: 0 | L3: 317.1966 | M3: 338.9584 | N3: 238.8556 | O3: 0.8348 | P3: 219.9983 | Q3: 80.4491 | R3: 101.9883 | S3: 59.4102 | T3: 12.1238 | U3: 61.7452 | V3: 46.8246 | W3: 24.8101 | X3: 41.016 | Y3: 34.8328 | Z3: 30.7549 | AA3: 18.8355 | AB3: 33.3544 | AC3: 15.352 | AD3: 46.1108 | AE3: 31.0168 | AF3: 45.2447 | AG3: 15.2614 | AH3: 26.519 | AI3: 32.2374 | AJ3: 8.8333 | AK3: 34.2585 | AL3: 29.2679 | AM3: 14.415 | AN3: 11.3145 | AO3: 27.9056 | AP3: 13.6716 | AQ3: 18.669 | AR3: 9.168 | AS3: 6.763 | AT3: 11.9093 | AU3: 8.5352 | AV3: 1.2639 | AW3: 5.142 | AX3: 6.9555 | AY3: 5.3142 | AZ3: 3.8416 | BA3: 6.447 | BB3: 8.0391 | BC3: 4.4617 | BD3: 2.083 | BE3: 5.1152 | BF3: 1.9961 | BG3: 3.3669 | BH3: 2.3822 | BI3: 1.3093 | BJ3: 1.5271 | BK3: 2.4028 | BL3: 0.8819 | BM3: 0.817 | BN3: 2.3543 | BO3: 0.6188 | BP3: 1.5329 | BQ3: 0.1887 | BR3: 0.4694 | BS3: 1.1959 | BT3: 1.1283 | BU3: 1.1069 | BV3: 0.2347 | BW3: 0.9256 | BX3: 0.4943 | BY3: 0.3586 | BZ3: 0.1196 | CA3: 0.6525 | CB3: 0 | CC3: 0.0988 | CD3: 0.657 | CE3: 0 | CF3: 0.1886 | CG3: 0.0656 | CH3: 0 | CI3: 0.2036 | CJ3: 0 | CK3: 0 | CL3: 0 | CM3: 0.2279 | CN3: 0 | CO3: 6.7796 | CP3: 14.3992 | CQ3: 14.5946 | CR3: 0.0576 | CS3: 18.2783 | CT3: 8.1662 | CU3: 11.9255 | CV3: 8.2382 | CW3: 1.7529 | CX3: 10.0249 | CY3: 8.5806 | CZ3: 4.9244 | DA3: 8.6116 | DB3: 7.9231 | DC3: 7.5671 | DD3: 4.8168 | DE3: 9.1291 | DF3: 4.4393 | DG3: 14.0274 | DH3: 9.9716 | DI3: 15.3621 | DJ3: 5.415 | DK3: 9.7913 | DL3: 12.5576 | DM3: 3.517 | DN3: 14.2434 | DO3: 12.7627 | DP3: 6.5448 | DQ3: 5.2042 | DR3: 13.3388 | DS3: 6.788 | DT3: 9.5377 | DU3: 4.8314 | DV3: 3.6329 | DW3: 6.6143 | DX3: 4.9265 | DY3: 0.7489 | DZ3: 3.0796 | EA3: 4.3093 | EB3: 3.3983 | EC3: 2.5027 | ED3: 4.2948 | EE3: 5.4997 | EF3: 3.1263 | EG3: 1.4909 | EH3: 3.7466 | EI3: 1.4843 | EJ3: 2.562 | EK3: 1.8651 | EL3: 1.0414 | EM3: 1.2308 | EN3: 1.9816 | EO3: 0.7466 | EP3: 0.6968 | EQ3: 2.0512 | ER3: 0.5496 | ES3: 1.3803 | ET3: 0.1739 | EU3: 0.437 | EV3: 1.1353 | EW3: 1.0917 | EX3: 1.0923 | EY3: 0.2326 | EZ3: 0.938 | FA3: 0.5114 | FB3: 0.3721 | FC3: 0.1261 | FD3: 0.7051 | FE3: 0 | FF3: 0.1092 | FG3: 0.7416 | FH3: 0 | FI3: 0.2182 | FJ3: 0.0772 | FK3: 0 | FL3: 0.2439 | FM3: 0 | FN3: 0 | FO3: 0 | FP3: 0.2888
A4: N1003 | B4: VWAD | C4: 110 | D4: VWAD.110.4 | G4: 3070.1213 | H4: 123.4252 | I4: 387.7514 | J4: 0.405325 | K4: 0.0055 | L4: 293.7648 | M4: 373.894 | N4: 635.3421 | O4: 440.3823 | P4: 289.9481 | Q4: 168.8169 | R4: 142.6821 | S4: 91.3621 | T4: 76.9893 | U4: 70.9454 | V4: 45.5949 | W4: 34.9054 | X4: 39.3115 | Y4: 36.0698 | Z4: 24.8657 | AA4: 17.6746 | AB4: 12.2921 | AC4: 9.8238 | AD4: 10.6354 | AE4: 7.4147 | AF4: 8.2239 | AG4: 7.1291 | AH4: 6.0742 | AI4: 9.5785 | AJ4: 12.357 | AK4: 11.5328 | AL4: 15.3064 | AM4: 12.0024 | AN4: 11.2057 | AO4: 10.2581 | AP4: 10.4352 | AQ4: 9.8037 | AR4: 10.4083 | AS4: 9.7103 | AT4: 10.9538 | AU4: 9.5229 | AV4: 11.6918 | AW4: 12.5518 | AX4: 10.9817 | AY4: 10.6236 | AZ4: 8.0632 | BA4: 5.9771 | BB4: 3.9851 | BC4: 3.0291 | BD4: 2.6899 | BE4: 1.7162 | BF4: 1.6919 | BG4: 1.0733 | BH4: 0.4331 | BI4: 0.5003 | BJ4: 0.6651 | BK4: 1.1019 | BL4: 0.2908 | BM4: 0.5247 | BN4: 0.5928 | BO4: 0.4136 | BP4: 0.6167 | BQ4: 0.2391 | BR4: 0.4701 | BS4: 0.2844 | BT4: 0.7505 | BU4: 0.1481 | BV4: 0.0598 | BW4: 0.0931 | BX4: 0.0904 | BY4: 0.073 | BZ4: 0.0915 | CA4: 0.0381 | CB4: 0.3484 | CC4: 0.0264 | CD4: 0 | CE4: 0 | CF4: 0 | CG4: 0 | CH4: 0 | CI4: 0 | CJ4: 0 | CK4: 0 | CL4: 0 | CM4: 0 | CN4: 0.0001 | CO4: 7.7697 | CP4: 14.8396 | CQ4: 34.9558 | CR4: 30.6502 | CS4: 24.7802 | CT4: 17.1385 | CU4: 16.7611 | CV4: 12.2108 | CW4: 11.4655 | CX4: 11.6641 | CY4: 8.2182 | CZ4: 6.8505 | DA4: 8.3344 | DB4: 8.2055 | DC4: 6.045 | DD4: 4.5667 | DE4: 3.3624 | DF4: 2.8538 | DG4: 3.2538 | DH4: 2.3894 | DI4: 2.7881 | DJ4: 2.5192 | DK4: 2.2445 | DL4: 3.6857 | DM4: 4.9441 | DN4: 4.808 | DO4: 6.6224 | DP4: 5.3541 | DQ4: 5.1874 | DR4: 4.9058 | DS4: 5.1727 | DT4: 4.9984 | DU4: 5.4759 | DV4: 5.251 | DW4: 6.1073 | DX4: 5.4594 | DY4: 6.8913 | DZ4: 7.5766 | EA4: 6.813 | EB4: 6.7701 | EC4: 5.2476 | ED4: 3.9953 | EE4: 2.7194 | EF4: 2.1187 | EG4: 1.9268 | EH4: 1.252 | EI4: 1.2607 | EJ4: 0.8171 | EK4: 0.3369 | EL4: 0.396 | EM4: 0.5402 | EN4: 0.9098 | EO4: 0.2436 | EP4: 0.45 | EQ4: 0.5166 | ER4: 0.3681 | ES4: 0.5573 | ET4: 0.219 | EU4: 0.4366 | EV4: 0.2705 | EW4: 0.7227 | EX4: 0.1456 | EY4: 0.0596 | EZ4: 0.0944 | FA4: 0.0931 | FB4: 0.0761 | FC4: 0.0968 | FD4: 0.041 | FE4: 0.3823 | FF4: 0.0293 | FG4: 0 | FH4: 0 | FI4: 0 | FJ4: 0 | FK4: 0 | FL4: 0 | FM4: 0 | FN4: 0 | FO4: 0 | FP4: 0
A5: N1006 | B5: VWAD | C5: 113 | D5: VWAD.113.4 | G5: 2593.1142 | H5: 164.7268 | I5: 517.5046 | J5: 0.60213333 | K5: 0.0345 | L5: 216.8309 | M5: 207.5319 | N5: 318.3106 | O5: 273.7926 | P5: 202.695 | Q5: 128.4362 | R5: 139.8679 | S5: 87.1783 | T5: 77.5847 | U5: 68.7557 | V5: 66.808 | W5: 52.027 | X5: 45.5244 | Y5: 34.0102 | Z5: 30.1178 | AA5: 24.3256 | AB5: 18.9431 | AC5: 17.1142 | AD5: 19.3599 | AE5: 26.1097 | AF5: 19.9086 | AG5: 14.5709 | AH5: 19.084 | AI5: 22.0472 | AJ5: 21.9878 | AK5: 25.4418 | AL5: 20.8825 | AM5: 27.061 | AN5: 22.8123 | AO5: 27.2765 | AP5: 25.2054 | AQ5: 34.1246 | AR5: 35.1132 | AS5: 24.6097 | AT5: 26.8333 | AU5: 18.693 | AV5: 15.9567 | AW5: 15.771 | AX5: 15.3261 | AY5: 16.7394 | AZ5: 11.7887 | BA5: 15.3766 | BB5: 11.5041 | BC5: 10.2398 | BD5: 7.8196 | BE5: 6.3674 | BF5: 4.8122 | BG5: 5.6023 | BH5: 3.7287 | BI5: 2.1805 | BJ5: 1.7388 | BK5: 1.6509 | BL5: 0.503 | BM5: 0.7784 | BN5: 1.0639 | BO5: 0.2528 | BP5: 0.4569 | BQ5: 0.3967 | BR5: 0.477 | BS5: 0.1658 | BT5: 0.0063 | BU5: 0.3346 | BV5: 0.0137 | BW5: 0 | BX5: 0 | BY5: 0 | BZ5: 0 | CA5: 0.0628 | CB5: 0.0206 | CC5: 0 | CD5: 0 | CE5: 0.0343 | CF5: 0 | CG5: 0 | CH5: 0 | CI5: 0 | CJ5: 0 | CK5: 0 | CL5: 0 | CM5: 0 | CN5: 0.0004 | CO5: 5.705 | CP5: 8.0317 | CQ5: 17.5746 | CR5: 19.0117 | CS5: 17.4011 | CT5: 13.0602 | CU5: 16.4911 | CV5: 11.6523 | CW5: 11.5317 | CX5: 11.3207 | CY5: 12.1129 | CZ5: 10.193 | DA5: 9.6348 | DB5: 7.7369 | DC5: 7.3381 | DD5: 6.2859 | DE5: 5.1979 | DF5: 4.975 | DG5: 5.9338 | DH5: 8.4154 | DI5: 6.726 | DJ5: 5.1477 | DK5: 7.0365 | DL5: 8.5078 | DM5: 8.7996 | DN5: 10.5884 | DO5: 9.0451 | DP5: 12.1051 | DQ5: 10.5602 | DR5: 13.0771 | DS5: 12.4881 | DT5: 17.4155 | DU5: 18.4716 | DV5: 13.3383 | DW5: 14.9381 | DX5: 10.7275 | DY5: 9.396 | DZ5: 9.5324 | EA5: 9.5138 | EB5: 10.6505 | EC5: 7.6829 | ED5: 10.2712 | EE5: 7.8581 | EF5: 7.1563 | EG5: 5.5843 | EH5: 4.6551 | EI5: 3.594 | EJ5: 4.2646 | EK5: 2.8985 | EL5: 1.7289 | EM5: 1.409 | EN5: 1.361 | EO5: 0.4217 | EP5: 0.6663 | EQ5: 0.927 | ER5: 0.2256 | ES5: 0.4141 | ET5: 0.3642 | EU5: 0.4456 | EV5: 0.1585 | EW5: 0.0061 | EX5: 0.3262 | EY5: 0.0137 | EZ5: 0 | FA5: 0 | FB5: 0 | FC5: 0 | FD5: 0.0675 | FE5: 0.0225 | FF5: 0 | FG5: 0 | FH5: 0.0391 | FI5: 0 | FJ5: 0 | FK5: 0 | FL5: 0 | FM5: 0 | FN5: 0 | FO5: 0 | FP5: 0
A6: N1007 | B6: =#N/A -> #N/A | C6: =#N/A -> #N/A | D6: =#N/A -> #N/A | G6: 3805.0056 | H6: 300.6121 | I6: 944.4006 | J6: 0.797675 | K6: 0 | L6: 318.7504 | M6: 291.6321 | N6: 398.4549 | O6: 283.4076 | P6: 187.5639 | Q6: 117.2967 | R6: 122.957 | S6: 82.3927 | T6: 67.5163 | U6: 72.5652 | V6: 69.1319 | W6: 58.9985 | X6: 58.7689 | Y6: 52.6793 | Z6: 50.8233 | AA6: 56.9947 | AB6: 57.1931 | AC6: 51.5096 | AD6: 56.0431 | AE6: 63.6671 | AF6: 64.0947 | AG6: 62.2617 | AH6: 62.5784 | AI6: 63.8472 | AJ6: 68.507 | AK6: 72.9236 | AL6: 70.7699 | AM6: 73.2751 | AN6: 67.5943 | AO6: 80.1769 | AP6: 71.3798 | AQ6: 70.2537 | AR6: 68.175 | AS6: 61.8112 | AT6: 73.6779 | AU6: 56.8702 | AV6: 37.6256 | AW6: 29.0175 | AX6: 28.4819 | AY6: 21.9609 | AZ6: 16.871 | BA6: 15.843 | BB6: 7.312 | BC6: 7.6784 | BD6: 7.7277 | BE6: 4.1542 | BF6: 3.6676 | BG6: 3.3459 | BH6: 2.2197 | BI6: 1.6033 | BJ6: 1.367 | BK6: 0.7211 | BL6: 0.6198 | BM6: 1.0961 | BN6: 1.4596 | BO6: 0.5068 | BP6: 0.5403 | BQ6: 0.4704 | BR6: 0.424 | BS6: 0.1957 | BT6: 0.0926 | BU6: 0.4856 | BV6: 0.0449 | BW6: 0.0544 | BX6: 0.0296 | BY6: 0.104 | BZ6: 0.0545 | CA6: 0.0386 | CB6: 0.1222 | CC6: 0.2864 | CD6: 0.0676 | CE6: 0.111 | CF6: 0.093 | CG6: 0.0159 | CH6: 0.2548 | CI6: 0 | CJ6: 0 | CK6: 0 | CL6: 0 | CM6: 0 | CN6: 0 | CO6: 8.3806 | CP6: 11.1687 | CQ6: 21.862 | CR6: 19.6583 | CS6: 16.121 | CT6: 11.9659 | CU6: 14.5473 | CV6: 10.9718 | CW6: 10.0443 | CX6: 11.9555 | CY6: 12.5209 | CZ6: 11.5622 | DA6: 12.4401 | DB6: 11.9997 | DC6: 12.3974 | DD6: 14.7661 | DE6: 15.7052 | DF6: 14.982 | DG6: 17.1581 | DH6: 20.5061 | DI6: 21.6716 | DJ6: 21.9669 | DK6: 23.1256 | DL6: 24.5982 | DM6: 27.4032 | DN6: 30.3485 | DO6: 30.6167 | DP6: 32.7727 | DQ6: 31.3263 | DR6: 38.4254 | DS6: 35.3514 | DT6: 35.8341 | DU6: 35.8746 | DV6: 33.4779 | DW6: 41.0665 | DX6: 32.614 | DY6: 22.1449 | DZ6: 17.5351 | EA6: 17.67 | EB6: 13.9856 | EC6: 10.9849 | ED6: 10.574 | EE6: 4.996 | EF6: 5.3686 | EG6: 5.5259 | EH6: 3.0327 | EI6: 2.7395 | EJ6: 2.5436 | EK6: 1.7287 | EL6: 1.2711 | EM6: 1.1053 | EN6: 0.5939 | EO6: 0.5212 | EP6: 0.9388 | EQ6: 1.2705 | ER6: 0.4478 | ES6: 0.4876 | ET6: 0.4916 | EU6: 0.396 | EV6: 0.186 | EW6: 0.0896 | EX6: 0.4761 | EY6: 0.0447 | EZ6: 0.0551 | FA6: 0.0306 | FB6: 0.1091 | FC6: 0.0577 | FD6: 0.0417 | FE6: 0.1334 | FF6: 0.3173 | FG6: 0.0761 | FH6: 0.126 | FI6: 0.1074 | FJ6: 0.0185 | FK6: 0.3019 | FL6: 0 | FM6: 0 | FN6: 0 | FO6: 0 | FP6: 0
A7: N1008 | B7: ADVW | C7: 229 | D7: ADVW.229.16 | G7: 4860.4815 | H7: 296.3589 | I7: 931.0394 | J7: 0.532275 | K7: 0 | L7: 290.1695 | M7: 272.2632 | N7: 489.3699 | O7: 575.4285 | P7: 478.9836 | Q7: 332.2738 | R7: 333.5504 | S7: 200.7279 | T7: 169.9577 | U7: 165.8835 | V7: 140.6839 | W7: 109.1165 | X7: 89.2331 | Y7: 72.5795 | Z7: 60.5953 | AA7: 52.1791 | AB7: 50.4253 | AC7: 40.0549 | AD7: 46.4844 | AE7: 52.6074 | AF7: 53.8481 | AG7: 36.2528 | AH7: 28.7576 | AI7: 26.947 | AJ7: 28.6309 | AK7: 36.0824 | AL7: 34.2312 | AM7: 30.4752 | AN7: 27.6682 | AO7: 34.0269 | AP7: 37.428 | AQ7: 32.566 | AR7: 36.2084 | AS7: 44.2947 | AT7: 49.8577 | AU7: 45.9957 | AV7: 33.223 | AW7: 28.7827 | AX7: 29.7466 | AY7: 21.6057 | AZ7: 17.153 | BA7: 18.1024 | BB7: 14.3446 | BC7: 14.3446 | BD7: 9.6193 | BE7: 9.5072 | BF7: 11.9466 | BG7: 10.7907 | BH7: 7.1082 | BI7: 5.7818 | BJ7: 4.4681 | BK7: 3.6023 | BL7: 1.9388 | BM7: 2.4167 | BN7: 2.5187 | BO7: 1.6959 | BP7: 0.9824 | BQ7: 0.4887 | BR7: 0.9402 | BS7: 0.1151 | BT7: 0.0069 | BU7: 0.4287 | BV7: 0.0797 | BW7: 0.0476 | BX7: 0.2226 | BY7: 0.0275 | BZ7: 0.2372 | CA7: 0 | CB7: 0.1574 | CC7: 0.3728 | CD7: 0 | CE7: 0 | CF7: 0 | CG7: 0 | CH7: 0 | CI7: 0 | CJ7: 0 | CK7: 0 | CL7: 0 | CM7: 0.1474 | CN7: 0 | CO7: 7.5824 | CP7: 10.557 | CQ7: 27.2336 | CR7: 40.266 | CS7: 41.1489 | CT7: 33.8289 | CU7: 39.2821 | CV7: 26.7823 | CW7: 25.306 | CX7: 27.3063 | CY7: 25.4497 | CZ7: 21.3578 | DA7: 18.8911 | DB7: 16.5105 | DC7: 14.7689 | DD7: 13.4964 | DE7: 13.8436 | DF7: 11.6368 | DG7: 14.2337 | DH7: 16.9639 | DI7: 18.1827 | DJ7: 12.8019 | DK7: 10.6206 | DL7: 10.3772 | DM7: 11.4552 | DN7: 15.0056 | DO7: 14.8221 | DP7: 13.6317 | DQ7: 12.8137 | DR7: 16.3104 | DS7: 18.5308 | DT7: 16.6284 | DU7: 19.0495 | DV7: 23.976 | DW7: 27.7984 | DX7: 26.4086 | DY7: 19.5659 | DZ7: 17.3948 | EA7: 18.4513 | EB7: 13.7521 | EC7: 11.1762 | ED7: 12.0839 | EE7: 9.7956 | EF7: 10.0316 | EG7: 6.878 | EH7: 6.9511 | EI7: 8.9141 | EJ7: 8.2132 | EK7: 5.5323 | EL7: 4.5788 | EM7: 3.6137 | EN7: 2.9654 | EO7: 1.6332 | EP7: 2.0694 | EQ7: 2.1908 | ER7: 1.5053 | ES7: 0.8882 | ET7: 0.448 | EU7: 0.8766 | EV7: 0.1097 | EW7: 0.0066 | EX7: 0.4204 | EY7: 0.0798 | EZ7: 0.0481 | FA7: 0.2301 | FB7: 0.0287 | FC7: 0.2511 | FD7: 0 | FE7: 0.1718 | FF7: 0.4107 | FG7: 0 | FH7: 0 | FI7: 0 | FJ7: 0 | FK7: 0 | FL7: 0 | FM7: 0 | FN7: 0 | FO7: 0 | FP7: 0.2068
A8: N1009 | B8: VWAD | C8: 34 | D8: VWAD.34.4 | G8: 1748.8858 | H8: 86.7061 | I8: 272.3952 | J8: 0.47745 | K8: 0.0287 | L8: 228.2021 | M8: 228.6715 | N8: 244.3511 | O8: 175.6024 | P8: 138.1198 | Q8: 93.5331 | R8: 82.7162 | S8: 50.07 | T8: 40.6416 | U8: 31.0002 | V8: 28.9715 | W8: 28.1618 | X8: 32.5799 | Y8: 21.1039 | Z8: 17.7185 | AA8: 12.7146 | AB8: 12.8468 | AC8: 13.2714 | AD8: 14.6252 | AE8: 13.0938 | AF8: 11.2066 | AG8: 15.705 | AH8: 14.0148 | AI8: 9.5956 | AJ8: 10.2079 | AK8: 11.7981 | AL8: 11.3301 | AM8: 10.7166 | AN8: 5.8184 | AO8: 10.8551 | AP8: 12.4392 | AQ8: 10.7973 | AR8: 10.1977 | AS8: 9.6371 | AT8: 12.988 | AU8: 11.7656 | AV8: 9.77 | AW8: 8.4714 | AX8: 9.4737 | AY8: 7.528 | AZ8: 5.7631 | BA8: 5.4109 | BB8: 3.9212 | BC8: 1.7229 | BD8: 1.056 | BE8: 1.9452 | BF8: 1.0056 | BG8: 0.9194 | BH8: 0.4943 | BI8: 0.814 | BJ8: 0.1394 | BK8: 1.081 | BL8: 0.1347 | BM8: 0.0745 | BN8: 0.0465 | BO8: 0.0328 | BP8: 0.2451 | BQ8: 0.1595 | BR8: 0.0254 | BS8: 0.2557 | BT8: 0 | BU8: 0 | BV8: 0 | BW8: 0 | BX8: 0 | BY8: 0 | BZ8: 0 | CA8: 0 | CB8: 0 | CC8: 0 | CD8: 0 | CE8: 0 | CF8: 0 | CG8: 0 | CH8: 0 | CI8: 0 | CJ8: 0 | CK8: 0 | CL8: 0 | CM8: 0 | CN8: 0.0003 | CO8: 5.8614 | CP8: 9.0564 | CQ8: 13.4091 | CR8: 12.2865 | CS8: 11.8425 | CT8: 9.5185 | CU8: 9.7375 | CV8: 6.6746 | CW8: 6.0401 | CX8: 5.0908 | CY8: 5.2543 | CZ8: 5.5281 | DA8: 6.8815 | DB8: 4.7967 | DC8: 4.3104 | DD8: 3.2949 | DE8: 3.5249 | DF8: 3.8625 | DG8: 4.489 | DH8: 4.2134 | DI8: 3.7826 | DJ8: 5.5427 | DK8: 5.1688 | DL8: 3.7035 | DM8: 4.0851 | DN8: 4.9159 | DO8: 4.9018 | DP8: 4.7885 | DQ8: 2.6954 | DR8: 5.2038 | DS8: 6.1679 | DT8: 5.5118 | DU8: 5.3656 | DV8: 5.2242 | DW8: 7.2392 | DX8: 6.7479 | DY8: 5.7582 | DZ8: 5.1181 | EA8: 5.8699 | EB8: 4.7911 | EC8: 3.7605 | ED8: 3.6048 | EE8: 2.6739 | EF8: 1.201 | EG8: 0.7551 | EH8: 1.4206 | EI8: 0.7496 | EJ8: 0.7 | EK8: 0.3853 | EL8: 0.6453 | EM8: 0.1126 | EN8: 0.8935 | EO8: 0.113 | EP8: 0.0638 | EQ8: 0.0405 | ER8: 0.0291 | ES8: 0.2216 | ET8: 0.1458 | EU8: 0.0238 | EV8: 0.2421 | EW8: 0 | EX8: 0 | EY8: 0 | EZ8: 0 | FA8: 0 | FB8: 0 | FC8: 0 | FD8: 0 | FE8: 0 | FF8: 0 | FG8: 0 | FH8: 0 | FI8: 0 | FJ8: 0 | FK8: 0 | FL8: 0 | FM8: 0 | FN8: 0 | FO8: 0 | FP8: 0
A9: N1011 | B9: VWAD | C9: 93 | D9: VWAD.93.4 | F9: =VLOOKUP(A9,[1]ROOT!$A$1:$C$1048576,3,0) -> #N/A | G9: 3607.0072 | H9: 154.2429 | I9: 484.5682 | J9: 0.42716 | K9: 0 | L9: 569.8465 | M9: 714.3384 | N9: 509.6048 | O9: 1.7962 | P9: 500.9732 | Q9: 165.0198 | R9: 225.6799 | S9: 123.5269 | T9: 21.015 | U9: 99.2841 | V9: 66.4479 | W9: 32.126 | X9: 50.984 | Y9: 45.2701 | Z9: 36.3888 | AA9: 22.4159 | AB9: 37.9932 | AC9: 13.1267 | AD9: 37.3292 | AE9: 20.4806 | AF9: 33.9153 | AG9: 9.4144 | AH9: 21.7202 | AI9: 22.0927 | AJ9: 4.6504 | AK9: 20.0577 | AL9: 19.54 | AM9: 9.0677 | AN9: 7.7793 | AO9: 23.649 | AP9: 10.7549 | AQ9: 17.8976 | AR9: 8.1278 | AS9: 6.9461 | AT9: 18.3848 | AU9: 18.7326 | AV9: 0.6439 | AW9: 10.3083 | AX9: 7.0043 | AY9: 3.0846 | AZ9: 3.5808 | BA9: 4.0737 | BB9: 4.1873 | BC9: 2.1778 | BD9: 2.4618 | BE9: 3.0782 | BF9: 1.5611 | BG9: 4.4142 | BH9: 2.6736 | BI9: 0.1947 | BJ9: 1.5041 | BK9: 1.7129 | BL9: 1.5659 | BM9: 0.403 | BN9: 0.4638 | BO9: 0.2359 | BP9: 0.9596 | BQ9: 0.322 | BR9: 0.338 | BS9: 0.4336 | BT9: 0.0629 | BU9: 0.1349 | BV9: 0.4237 | BW9: 0.0614 | BX9: 0 | BY9: 0.065 | BZ9: 0 | CA9: 0.0137 | CB9: 0 | CC9: 0.0861 | CD9: 0.2947 | CE9: 0.3272 | CF9: 0.0296 | CG9: 0.1322 | CH9: 0 | CI9: 0 | CJ9: 0 | CK9: 0 | CL9: 0 | CM9: 0.1628 | CN9: 0 | CO9: 12.2274 | CP9: 30.4432 | CQ9: 31.1431 | CR9: 0.1243 | CS9: 41.8418 | CT9: 16.7633 | CU9: 26.3227 | CV9: 17.1355 | CW9: 3.0384 | CX9: 16.1237 | CY9: 12.1677 | CZ9: 6.3687 | DA9: 10.6768 | DB9: 10.2895 | DC9: 8.9374 | DD9: 5.7189 | DE9: 10.3956 | DF9: 3.7959 | DG9: 11.3618 | DH9: 6.5888 | DI9: 11.559 | DJ9: 3.3395 | DK9: 8.0135 | DL9: 8.6268 | DM9: 1.8433 | DN9: 8.3288 | DO9: 8.5289 | DP9: 4.1081 | DQ9: 3.5807 | DR9: 11.3422 | DS9: 5.336 | DT9: 9.143 | DU9: 4.298 | DV9: 3.7308 | DW9: 10.213 | DX9: 10.8046 | DY9: 0.3814 | DZ9: 6.2094 | EA9: 4.3421 | EB9: 1.9713 | EC9: 2.3238 | ED9: 2.714 | EE9: 2.8651 | EF9: 1.5267 | EG9: 1.7618 | EH9: 2.2514 | EI9: 1.1607 | EJ9: 3.3607 | EK9: 2.0961 | EL9: 0.1551 | EM9: 1.2117 | EN9: 1.4148 | EO9: 1.3236 | EP9: 0.3439 | EQ9: 0.4045 | ER9: 0.2095 | ES9: 0.8668 | ET9: 0.2967 | EU9: 0.3142 | EV9: 0.4119 | EW9: 0.0608 | EX9: 0.132 | EY9: 0.4204 | EZ9: 0.0621 | FA9: 0 | FB9: 0.0679 | FC9: 0 | FD9: 0.0149 | FE9: 0 | FF9: 0.0948 | FG9: 0.349 | FH9: 0.3719 | FI9: 0.0341 | FJ9: 0.1556 | FK9: 0 | FL9: 0 | FM9: 0 | FN9: 0 | FO9: 0 | FP9: 0.2075
A10: N1013 | B10: VWAD | C10: 132 | D10: VWAD.132.4 | G10: 4021.144 | H10: 278.5149 | I10: 874.9805 | J10: 0.7852 | K10: 0.0317 | L10: 12.0005 | M10: 33.5589 | N10: 328.7657 | O10: 497.1979 | P10: 417.2418 | Q10: 580.4393 | R10: 277.8119 | S10: 237.5606 | T10: 176.6227 | U10: 190.716 | V10: 86.9068 | W10: 137.4172 | X10: 85.2611 | Y10: 60.1336 | Z10: 67.8099 | AA10: 69.1235 | AB10: 56.1509 | AC10: 37.4992 | AD10: 42.1048 | AE10: 33.8439 | AF10: 42.4206 | AG10: 16.5781 | AH10: 33.4005 | AI10: 40.5605 | AJ10: 29.2172 | AK10: 38.5226 | AL10: 20.1287 | AM10: 27.2288 | AN10: 32.4135 | AO10: 29.4003 | AP10: 24.5843 | AQ10: 29.5993 | AR10: 28.0961 | AS10: 20.7354 | AT10: 33.1793 | AU10: 30.0713 | AV10: 15.5314 | AW10: 18.3322 | AX10: 15.5876 | AY10: 8.1567 | AZ10: 10.463 | BA10: 5.9363 | BB10: 10.2449 | BC10: 7.0076 | BD10: 3.6535 | BE10: 3.5681 | BF10: 2.1626 | BG10: 2.1206 | BH10: 1.3056 | BI10: 1.7721 | BJ10: 2.2929 | BK10: 1.3401 | BL10: 0.958 | BM10: 0.8456 | BN10: 0.3252 | BO10: 0.3743 | BP10: 0.2056 | BQ10: 0.4023 | BR10: 0.2554 | BS10: 0.6059 | BT10: 0.0972 | BU10: 0.2332 | BV10: 0.458 | BW10: 0.1597 | BX10: 0.0275 | BY10: 0.2109 | BZ10: 0.0497 | CA10: 0.0596 | CB10: 0.0597 | CC10: 0.0397 | CD10: 0.0338 | CE10: 0.0824 | CF10: 0.393 | CG10: 0.0386 | CH10: 0.0338 | CI10: 0.0069 | CJ10: 0 | CK10: 0 | CL10: 0 | CM10: 0.1644 | CN10: 0.0005 | CO10: 0.3253 | CP10: 1.3484 | CQ10: 18.7914 | CR10: 35.3068 | CS10: 34.9246 | CT10: 58.4189 | CU10: 33.0504 | CV10: 31.6617 | CW10: 25.9192 | CX10: 31.6154 | CY10: 15.7683 | CZ10: 26.9245 | DA10: 18.3901 | DB10: 13.6426 | DC10: 16.4149 | DD10: 17.8576 | DE10: 15.4993 | DF10: 10.9016 | DG10: 12.9093 | DH10: 10.8441 | DI10: 14.3951 | DJ10: 5.9018 | DK10: 12.2619 | DL10: 15.6914 | DM10: 11.7008 | DN10: 16.0583 | DO10: 8.7266 | DP10: 12.1248 | DQ10: 15.0138 | DR10: 14.1569 | DS10: 12.0995 | DT10: 15.0824 | DU10: 14.8112 | DV10: 11.1971 | DW10: 18.4196 | DX10: 17.2659 | DY10: 9.1801 | DZ10: 11.0394 | EA10: 9.6779 | EB10: 5.1986 | EC10: 6.838 | ED10: 3.9417 | EE10: 6.982 | EF10: 4.9131 | EG10: 2.6209 | EH10: 2.6046 | EI10: 1.6087 | EJ10: 1.6134 | EK10: 1.0158 | EL10: 1.405 | EM10: 1.8563 | EN10: 1.1086 | EO10: 0.8035 | EP10: 0.7243 | EQ10: 0.2843 | ER10: 0.3319 | ES10: 0.1853 | ET10: 0.3705 | EU10: 0.2393 | EV10: 0.5767 | EW10: 0.094 | EX10: 0.2298 | EY10: 0.4579 | EZ10: 0.1622 | FA10: 0.0282 | FB10: 0.2203 | FC10: 0.0528 | FD10: 0.0641 | FE10: 0.065 | FF10: 0.044 | FG10: 0.0381 | FH10: 0.0935 | FI10: 0.4538 | FJ10: 0.0453 | FK10: 0.0403 | FL10: 0.0083 | FM10: 0 | FN10: 0 | FO10: 0 | FP10: 0.2518
A11: N1016 | B11: =#N/A -> #N/A | C11: =#N/A -> #N/A | D11: =#N/A -> #N/A | G11: 2435.1772 | H11: 209.2967 | I11: 657.5249 | J11: 0.7793 | K11: 0 | L11: 176.946 | M11: 163.714 | N11: 259.0864 | O11: 182.8252 | P11: 117.212 | Q11: 79.7303 | R11: 75.366 | S11: 51.7665 | T11: 49.3118 | U11: 37.0043 | V11: 37.8611 | W11: 31.9411 | X11: 26.2037 | Y11: 22.6433 | Z11: 23.6778 | AA11: 24.0854 | AB11: 23.1042 | AC11: 24.9109 | AD11: 29.0367 | AE11: 40.5873 | AF11: 42.6566 | AG11: 41.4448 | AH11: 38.7104 | AI11: 34.942 | AJ11: 45.352 | AK11: 53.6739 | AL11: 57.3407 | AM11: 53.6459 | AN11: 54.5856 | AO11: 51.9021 | AP11: 52.836 | AQ11: 56.0088 | AR11: 52.6543 | AS11: 55.2999 | AT11: 46.8208 | AU11: 38.7711 | AV11: 28.7527 | AW11: 26.9802 | AX11: 25.7331 | AY11: 18.5936 | AZ11: 12.7881 | BA11: 13.1397 | BB11: 8.564 | BC11: 7.2034 | BD11: 5.4737 | BE11: 4.7613 | BF11: 3.478 | BG11: 4.4476 | BH11: 3.5391 | BI11: 2.9097 | BJ11: 2.1521 | BK11: 1.5652 | BL11: 1.08 | BM11: 0.8967 | BN11: 1.0041 | BO11: 1.0936 | BP11: 0.7214 | BQ11: 0.8536 | BR11: 0.544 | BS11: 0.6193 | BT11: 0.4338 | BU11: 0.283 | BV11: 0.3938 | BW11: 0.397 | BX11: 0.0846 | BY11: 0.2406 | BZ11: 0.1608 | CA11: 0.2072 | CB11: 0.0783 | CC11: 0.054 | CD11: 0.0551 | CE11: 0.0752 | CF11: 0.2505 | CG11: 0.1274 | CH11: 0.0761 | CI11: 0.1051 | CJ11: 0.0244 | CK11: 0.0201 | CL11: 0.0222 | CM11: 0.1348 | CN11: 0 | CO11: 4.6949 | CP11: 6.3535 | CQ11: 14.2498 | CR11: 12.6941 | CS11: 10.0599 | CT11: 8.1012 | CU11: 8.8855 | CV11: 6.9072 | CW11: 7.3223 | CX11: 6.0976 | CY11: 6.8476 | CZ11: 6.2579 | DA11: 5.5464 | DB11: 5.1525 | DC11: 5.77 | DD11: 6.2365 | DE11: 6.3403 | DF11: 7.2529 | DG11: 8.8973 | DH11: 13.0752 | DI11: 14.4214 | DJ11: 14.6297 | DK11: 14.2873 | DL11: 13.4578 | DM11: 18.1629 | DN11: 22.3651 | DO11: 24.8046 | DP11: 23.9813 | DQ11: 25.2669 | DR11: 24.8633 | DS11: 26.1733 | DT11: 28.5998 | DU11: 27.7013 | DV11: 29.9222 | DW11: 26.1231 | DX11: 22.2306 | DY11: 16.9313 | DZ11: 16.2974 | EA11: 15.9717 | EB11: 11.8375 | EC11: 8.3282 | ED11: 8.7655 | EE11: 5.8405 | EF11: 5.0341 | EG11: 3.9113 | EH11: 3.4699 | EI11: 2.5901 | EJ11: 3.3931 | EK11: 2.7481 | EL11: 2.3038 | EM11: 1.7428 | EN11: 1.2897 | EO11: 0.9061 | EP11: 0.7674 | EQ11: 0.8739 | ER11: 0.9675 | ES11: 0.652 | ET11: 0.7862 | EU11: 0.5085 | EV11: 0.5898 | EW11: 0.4188 | EX11: 0.2779 | EY11: 0.3916 | EZ11: 0.4031 | FA11: 0.0872 | FB11: 0.252 | FC11: 0.1705 | FD11: 0.2234 | FE11: 0.0854 | FF11: 0.0598 | FG11: 0.0617 | FH11: 0.0857 | FI11: 0.2896 | FJ11: 0.1486 | FK11: 0.0902 | FL11: 0.1262 | FM11: 0.0296 | FN11: 0.0248 | FO11: 0.0277 | FP11: 0.174
A12: N1017 | B12: ADVW | C12: 232 | D12: ADVW.232.4 | F12: 3.7361 | G12: 3422.334 | H12: 204.5562 | I12: 642.6322 | J12: 0.6112 | K12: 0 | L12: 485.2995 | M12: 589.9582 | N12: 391.0086 | O12: 0.6957 | P12: 338.5125 | Q12: 114.2993 | R12: 149.1622 | S12: 86.4309 | T12: 17.4238 | U12: 83.9934 | V12: 67.5302 | W12: 42.0356 | X12: 53.1896 | Y12: 41.3924 | Z12: 37.7218 | AA12: 24.8412 | AB12: 43.8007 | AC12: 19.3015 | AD12: 50.2133 | AE12: 29.2568 | AF12: 54.4321 | AG12: 29.9338 | AH12: 45.2461 | AI12: 66.1634 | AJ12: 13.3364 | AK12: 78.2103 | AL12: 71.1495 | AM12: 35.1053 | AN12: 25.4004 | AO12: 55.7075 | AP12: 34.3522 | AQ12: 36.2387 | AR12: 23.244 | AS12: 28.2806 | AT12: 34.2436 | AU12: 29.8976 | AV12: 0.8958 | AW12: 19.6141 | AX12: 13.7233 | AY12: 12.5721 | AZ12: 9.2797 | BA12: 6.4326 | BB12: 10.7757 | BC12: 3.5112 | BD12: 2.6786 | BE12: 2.9133 | BF12: 0.6966 | BG12: 3.0886 | BH12: 1.8481 | BI12: 0.6649 | BJ12: 1.2882 | BK12: 0.8657 | BL12: 1.3453 | BM12: 0.2015 | BN12: 0.1576 | BO12: 0 | BP12: 0.0137 | BQ12: 0 | BR12: 0 | BS12: 0.2083 | BT12: 0.3555 | BU12: 0 | BV12: 0 | BW12: 0 | BX12: 0 | BY12: 0.1559 | BZ12: 0.0629 | CA12: 0 | CB12: 0 | CC12: 0 | CD12: 0 | CE12: 0.1645 | CF12: 0 | CG12: 0 | CH12: 0 | CI12: 0 | CJ12: 0 | CK12: 0 | CL12: 0 | CM12: 0 | CN12: 0 | CO12: 10.4093 | CP12: 25.0797 | CQ12: 23.8707 | CR12: 0.0481 | CS12: 28.1643 | CT12: 11.6092 | CU12: 17.45 | CV12: 12.0048 | CW12: 2.5192 | CX12: 13.6271 | CY12: 12.3351 | CZ12: 8.3457 | DA12: 11.197 | DB12: 9.4106 | DC12: 9.2434 | DD12: 6.366 | DE12: 12.0011 | DF12: 5.5815 | DG12: 15.2766 | DH12: 9.3942 | DI12: 18.4706 | DJ12: 10.6326 | DK12: 16.7377 | DL12: 25.7472 | DM12: 5.3146 | DN12: 32.4858 | DO12: 31.0191 | DP12: 15.936 | DQ12: 11.6789 | DR12: 26.6276 | DS12: 17.0548 | DT12: 18.5566 | DU12: 12.2394 | DV12: 15.1949 | DW12: 19.0506 | DX12: 17.2648 | DY12: 0.5307 | DZ12: 11.7451 | EA12: 8.504 | EB12: 8.037 | EC12: 6.055 | ED12: 4.268 | EE12: 7.3484 | EF12: 2.4594 | EG12: 1.9176 | EH12: 2.1346 | EI12: 0.518 | EJ12: 2.348 | EK12: 1.4433 | EL12: 0.5301 | EM12: 1.0383 | EN12: 0.7161 | EO12: 1.1335 | EP12: 0.1723 | EQ12: 0.1383 | ER12: 0 | ES12: 0.0125 | ET12: 0 | EU12: 0 | EV12: 0.2888 | EW12: 0.3451 | EX12: 0 | EY12: 0 | EZ12: 0 | FA12: 0 | FB12: 0.1617 | FC12: 0.0903 | FD12: 0 | FE12: 0 | FF12: 0 | FG12: 0 | FH12: 0.1868 | FI12: 0 | FJ12: 0 | FK12: 0 | FL12: 0 | FM12: 0 | FN12: 0 | FO12: 0 | FP12: 0
A13: N1019 | B13: ADVW | C13: 290 | D13: ADVW.290.4 | G13: 4310.778 | H13: 204.2557 | I13: 641.688 | J13: 0.48185 | K13: 0.0452 | L13: 484.5817 | M13: 496.6873 | N13: 798.946 | O13: 561.5307 | P13: 344.8129 | Q13: 212.0202 | R13: 179.0519 | S13: 95.2503 | T13: 81.4573 | U13: 66.6244 | V13: 58.3537 | W13: 47.2475 | X13: 49.0332 | Y13: 41.7036 | Z13: 32.9567 | AA13: 35.1936 | AB13: 30.4989 | AC13: 32.6431 | AD13: 32.7051 | AE13: 29.2356 | AF13: 33.1409 | AG13: 35.6725 | AH13: 35.4535 | AI13: 33.5038 | AJ13: 30.4718 | AK13: 38.5387 | AL13: 40.771 | AM13: 37.4577 | AN13: 39.6455 | AO13: 46.9296 | AP13: 37.2984 | AQ13: 33.3911 | AR13: 26.666 | AS13: 22.8749 | AT13: 17.9082 | AU13: 17.9568 | AV13: 12.1366 | AW13: 9.167 | AX13: 8.0799 | AY13: 6.9863 | AZ13: 6.8909 | BA13: 4.2758 | BB13: 3.0199 | BC13: 2.7586 | BD13: 2.6879 | BE13: 3.1548 | BF13: 1.4511 | BG13: 2.0734 | BH13: 1.6598 | BI13: 1.0676 | BJ13: 1.1135 | BK13: 0.5477 | BL13: 0.3809 | BM13: 0.3775 | BN13: 0.284 | BO13: 0.2296 | BP13: 0.1636 | BQ13: 0.0491 | BR13: 0.0999 | BS13: 0.0765 | BT13: 0.0654 | BU13: 0.0829 | BV13: 0.1209 | BW13: 0.0655 | BX13: 0.1531 | BY13: 0 | BZ13: 0.0296 | CA13: 0 | CB13: 0.075 | CC13: 0.0415 | CD13: 0 | CE13: 0 | CF13: 0 | CG13: 0 | CH13: 0 | CI13: 0 | CJ13: 0 | CK13: 0 | CL13: 0 | CM13: 0.1806 | CN13: 0.0006 | CO13: 12.6554 | CP13: 19.6336 | CQ13: 43.9495 | CR13: 38.9695 | CS13: 29.5024 | CT13: 21.5518 | CU13: 21.0158 | CV13: 12.7188 | CW13: 12.1233 | CX13: 10.9779 | CY13: 10.5535 | CZ13: 9.2723 | DA13: 10.3844 | DB13: 9.4898 | DC13: 8.0379 | DD13: 9.1172 | DE13: 8.378 | DF13: 9.4959 | DG13: 10.0162 | DH13: 9.3915 | DI13: 11.199 | DJ13: 12.6104 | DK13: 13.0822 | DL13: 12.9012 | DM13: 12.1907 | DN13: 16.0476 | DO13: 17.6329 | DP13: 16.7726 | DQ13: 18.3568 | DR13: 22.4796 | DS13: 18.4563 | DT13: 17.0733 | DU13: 14.0155 | DV13: 12.3835 | DW13: 9.9768 | DX13: 10.2944 | DY13: 7.1454 | DZ13: 5.5394 | EA13: 5.0115 | EB13: 4.4492 | EC13: 4.4906 | ED13: 2.8538 | EE13: 2.0614 | EF13: 1.9281 | EG13: 1.9179 | EH13: 2.2996 | EI13: 1.0832 | EJ13: 1.5811 | EK13: 1.2913 | EL13: 0.8474 | EM13: 0.8988 | EN13: 0.4508 | EO13: 0.3183 | EP13: 0.323 | EQ13: 0.2464 | ER13: 0.2026 | ES13: 0.1483 | ET13: 0.0452 | EU13: 0.0937 | EV13: 0.0731 | EW13: 0.0628 | EX13: 0.081 | EY13: 0.1209 | EZ13: 0.0661 | FA13: 0.1577 | FB13: 0 | FC13: 0.0315 | FD13: 0 | FE13: 0.0813 | FF13: 0.0458 | FG13: 0 | FH13: 0 | FI13: 0 | FJ13: 0 | FK13: 0 | FL13: 0 | FM13: 0 | FN13: 0 | FO13: 0 | FP13: 0.2365
A14: N1020 | B14: VWAD | C14: 71 | D14: VWAD.71.4 | G14: 2770.7851 | H14: 179.4354 | I14: 563.7129 | J14: 0.6406 | K14: 0.0231 | L14: 312.4906 | M14: 304.5197 | N14: 372.789 | O14: 279.5538 | P14: 187.9168 | Q14: 112.1812 | R14: 112.7161 | S14: 61.8261 | T14: 55.6948 | U14: 43.2795 | V14: 42.0038 | W14: 41.4886 | X14: 47.443 | Y14: 36.3575 | Z14: 33.1078 | AA14: 26.1974 | AB14: 27.7842 | AC14: 28.5826 | AD14: 23.3459 | AE14: 25.3366 | AF14: 17.5555 | AG14: 16.3311 | AH14: 15.9775 | AI14: 15.7845 | AJ14: 16.8689 | AK14: 22.193 | AL14: 22.9739 | AM14: 23.8427 | AN14: 21.5964 | AO14: 25.3808 | AP14: 26.9178 | AQ14: 23.2278 | AR14: 27.1303 | AS14: 31.3453 | AT14: 32.5353 | AU14: 29.4322 | AV14: 24.7366 | AW14: 26.0718 | AX14: 22.6104 | AY14: 25.2651 | AZ14: 19.3839 | BA14: 18.0497 | BB14: 14.632 | BC14: 15.2192 | BD14: 15.9583 | BE14: 8.4801 | BF14: 7.7875 | BG14: 8.0727 | BH14: 3.9867 | BI14: 2.1008 | BJ14: 2.5797 | BK14: 1.8654 | BL14: 2.121 | BM14: 1.1713 | BN14: 1.3854 | BO14: 0.8517 | BP14: 1.0952 | BQ14: 0.1489 | BR14: 0.1706 | BS14: 0.3981 | BT14: 0.0856 | BU14: 0.2576 | BV14: 0.159 | BW14: 0.038 | BX14: 0.0872 | BY14: 0.0296 | BZ14: 0.0518 | CA14: 0 | CB14: 0.284 | CC14: 0 | CD14: 0 | CE14: 0 | CF14: 0 | CG14: 0.065 | CH14: 0.0475 | CI14: 0 | CJ14: 0.1077 | CK14: 0 | CL14: 0 | CM14: 0.0586 | CN14: 0.0002 | CO14: 8.0391 | CP14: 12.0462 | CQ14: 20.5282 | CR14: 19.4624 | CS14: 16.096 | CT14: 11.4342 | CU14: 13.2301 | CV14: 8.2462 | CW14: 8.3012 | CX14: 7.1099 | CY14: 7.6157 | CZ14: 8.1277 | DA14: 10.0803 | DB14: 8.2695 | DC14: 8.0668 | DD14: 6.7805 | DE14: 7.6329 | DF14: 8.3114 | DG14: 7.1481 | DH14: 8.1535 | DI14: 5.9329 | DJ14: 5.7579 | DK14: 5.8983 | DL14: 6.0827 | DM14: 6.7628 | DN14: 9.2555 | DO14: 9.9381 | DP14: 10.6572 | DQ14: 9.9877 | DR14: 12.1554 | DS14: 13.3331 | DT14: 11.8657 | DU14: 14.3033 | DV14: 16.9822 | DW14: 18.1267 | DX14: 16.8918 | DY14: 14.5589 | DZ14: 15.7665 | EA14: 14.0129 | EB14: 16.0996 | EC14: 12.6247 | ED14: 12.0416 | EE14: 9.9891 | EF14: 10.6417 | EG14: 11.4109 | EH14: 6.1861 | EI14: 5.8087 | EJ14: 6.1382 | EK14: 3.0999 | EL14: 1.6637 | EM14: 2.0877 | EN14: 1.5344 | EO14: 1.7817 | EP14: 1.0012 | EQ14: 1.2053 | ER14: 0.7533 | ES14: 0.9894 | ET14: 0.1361 | EU14: 0.1588 | EV14: 0.3794 | EW14: 0.0822 | EX14: 0.2537 | EY14: 0.1586 | EZ14: 0.0385 | FA14: 0.0901 | FB14: 0.0307 | FC14: 0.0553 | FD14: 0 | FE14: 0.3095 | FF14: 0 | FG14: 0 | FH14: 0 | FI14: 0 | FJ14: 0.0764 | FK14: 0.0565 | FL14: 0 | FM14: 0.1307 | FN14: 0 | FO14: 0 | FP14: 0.0772
A15: N1102 | B15: F0 | C15: AP13 | D15: F0.AP13 | G15: 1936.9365 | H15: 221.9747 | I15: 697.3541 | J15: 1.1499 | K15: 0.1111 | L15: 14.6172 | M15: 21.2723 | N15: 64.4091 | O15: 76.2393 | P15: 81.9768 | Q15: 135.345 | R15: 84.3346 | S15: 83.1017 | T15: 75.0063 | U15: 95.3265 | V15: 43.1979 | W15: 79.5887 | X15: 59.0014 | Y15: 41.1745 | Z15: 46.0106 | AA15: 55.0691 | AB15: 54.1168 | AC15: 35.3027 | AD15: 43.0124 | AE15: 34.3551 | AF15: 39.1824 | AG15: 19.4447 | AH15: 28.3776 | AI15: 37.2003 | AJ15: 18.9553 | AK15: 26.2478 | AL15: 19.3617 | AM15: 17.6934 | AN15: 20.9927 | AO15: 23.1037 | AP15: 20.2925 | AQ15: 24.097 | AR15: 23.6183 | AS15: 20.497 | AT15: 31.1848 | AU15: 26.2489 | AV15: 17.1938 | AW15: 17.3005 | AX15: 30.7346 | AY15: 15.664 | AZ15: 23.6084 | BA15: 12.3272 | BB15: 23.6688 | BC15: 21.1518 | BD15: 17.4353 | BE15: 15.7968 | BF15: 12.0135 | BG15: 13.4834 | BH15: 12.5614 | BI15: 9.7666 | BJ15: 8.2835 | BK15: 9.9612 | BL15: 6.6415 | BM15: 7.7735 | BN15: 4.6185 | BO15: 6.1699 | BP15: 3.4341 | BQ15: 3.3476 | BR15: 1.6911 | BS15: 4.2024 | BT15: 1.9494 | BU15: 1.6976 | BV15: 2.5058 | BW15: 2.2714 | BX15: 1.0738 | BY15: 0.7039 | BZ15: 1.0512 | CA15: 0.9743 | CB15: 0.1798 | CC15: 1.0646 | CD15: 1.0619 | CE15: 0.7733 | CF15: 0.4024 | CG15: 0.2141 | CH15: 0.2869 | CI15: 0.2394 | CJ15: 0.376 | CK15: 0.2015 | CL15: 0.1396 | CM15: 1.8728 | CN15: 0.0014 | CO15: 0.386 | CP15: 0.8384 | CQ15: 3.6098 | CR15: 5.5074 | CS15: 7.0401 | CT15: 13.6984 | CU15: 10.0183 | CV15: 11.0685 | CW15: 11.0038 | CX15: 15.8374 | CY15: 7.8604 | CZ15: 15.5588 | DA15: 12.7238 | DB15: 9.366 | DC15: 11.1455 | DD15: 14.2096 | DE15: 14.944 | DF15: 10.2551 | DG15: 13.1465 | DH15: 10.9965 | DI15: 13.2763 | DJ15: 6.9553 | DK15: 10.4216 | DL15: 14.3725 | DM15: 7.5821 | DN15: 10.9321 | DO15: 8.3908 | DP15: 7.8802 | DQ15: 9.721 | DR15: 11.1124 | DS15: 10.0255 | DT15: 12.274 | DU15: 12.423 | DV15: 11.0803 | DW15: 17.3302 | DX15: 15.0738 | DY15: 10.1642 | DZ15: 10.414 | EA15: 19.0717 | EB15: 9.9845 | EC15: 15.4172 | ED15: 8.1876 | EE15: 16.1154 | EF15: 14.8285 | EG15: 12.5095 | EH15: 11.5454 | EI15: 8.9463 | EJ15: 10.247 | EK15: 9.7758 | EL15: 7.7406 | EM15: 6.6841 | EN15: 8.2057 | EO15: 5.5977 | EP15: 6.6433 | EQ15: 4.0336 | ER15: 5.4761 | ES15: 3.0959 | ET15: 3.0704 | EU15: 1.5782 | EV15: 3.9976 | EW15: 1.8847 | EX15: 1.6631 | EY15: 2.4932 | EZ15: 2.3049 | FA15: 1.1048 | FB15: 0.7336 | FC15: 1.1132 | FD15: 1.0494 | FE15: 0.1961 | FF15: 1.179 | FG15: 1.1922 | FH15: 0.8799 | FI15: 0.4645 | FJ15: 0.2499 | FK15: 0.3417 | FL15: 0.2871 | FM15: 0.4562 | FN15: 0.2484 | FO15: 0.1741 | FP15: 2.6327
A16: N1105 | B16: VWAD | C16: 173 | D16: VWAD.173.4 | G16: 2853.9117 | H16: 183.6711 | I16: 577.0201 | J16: 0.64085 | K16: 0.3333 | L16: 277.8748 | M16: 244.3544 | N16: 331.4877 | O16: 262.089 | P16: 203.1456 | Q16: 135.3996 | R16: 133.1445 | S16: 72.0833 | T16: 67.4669 | U16: 59.2963 | V16: 52.2908 | W16: 52.4905 | X16: 58.0822 | Y16: 41.7002 | Z16: 36.8732 | AA16: 35.0804 | AB16: 34.8231 | AC16: 35.312 | AD16: 43.762 | AE16: 43.0889 | AF16: 40.1231 | AG16: 36.0593 | AH16: 38.4774 | AI16: 34.6663 | AJ16: 44.9116 | AK16: 52.8974 | AL16: 42.6397 | AM16: 40.5937 | AN16: 31.9209 | AO16: 33.0601 | AP16: 30.0263 | AQ16: 30.9809 | AR16: 27.5736 | AS16: 29.963 | AT16: 24.1971 | AU16: 17.5836 | AV16: 12.9289 | AW16: 9.6201 | AX16: 8.2776 | AY16: 6.2956 | AZ16: 4.5594 | BA16: 2.8942 | BB16: 2.738 | BC16: 4.4536 | BD16: 3.1678 | BE16: 1.5421 | BF16: 2.0483 | BG16: 1.4462 | BH16: 0.611 | BI16: 1.8116 | BJ16: 2.1671 | BK16: 1.9422 | BL16: 0.8607 | BM16: 1.0915 | BN16: 0.9018 | BO16: 0.811 | BP16: 1.1046 | BQ16: 0.3908 | BR16: 0.5199 | BS16: 0.5838 | BT16: 0.7679 | BU16: 0.7359 | BV16: 0.1014 | BW16: 0.2962 | BX16: 0.3567 | BY16: 0.4666 | BZ16: 0.0322 | CA16: 0.2254 | CB16: 0.1019 | CC16: 0.226 | CD16: 0.0127 | CE16: 0.2191 | CF16: 0.0069 | CG16: 0.0745 | CH16: 0 | CI16: 0 | CJ16: 0.0654 | CK16: 0 | CL16: 0 | CM16: 0.436 | CN16: 0.004 | CO16: 7.2747 | CP16: 9.4987 | CQ16: 18.2512 | CR16: 18.267 | CS16: 17.4436 | CT16: 13.7802 | CU16: 15.6895 | CV16: 9.6086 | CW16: 10.0394 | CX16: 9.7641 | CY16: 9.4429 | CZ16: 10.3068 | DA16: 12.2965 | DB16: 9.5007 | DC16: 8.9824 | DD16: 9.0888 | DE16: 9.5622 | DF16: 10.2716 | DG16: 13.3916 | DH16: 13.8651 | DI16: 13.5533 | DJ16: 12.7214 | DK16: 14.2023 | DL16: 13.3652 | DM16: 17.9737 | DN16: 21.9888 | DO16: 18.4372 | DP16: 18.1584 | DQ16: 14.7595 | DR16: 15.8377 | DS16: 14.8578 | DT16: 15.8298 | DU16: 14.499 | DV16: 16.2045 | DW16: 13.4794 | DX16: 10.0826 | DY16: 7.602 | DZ16: 5.8142 | EA16: 5.1326 | EB16: 4.01 | EC16: 2.9667 | ED16: 1.9301 | EE16: 1.8731 | EF16: 3.1161 | EG16: 2.2661 | EH16: 1.1257 | EI16: 1.5299 | EJ16: 1.1011 | EK16: 0.4743 | EL16: 1.4348 | EM16: 1.7609 | EN16: 1.6031 | EO16: 0.7225 | EP16: 0.9351 | EQ16: 0.7844 | ER16: 0.7205 | ES16: 0.9965 | ET16: 0.3591 | EU16: 0.487 | EV16: 0.5762 | EW16: 0.7378 | EX16: 0.7228 | EY16: 0.1011 | EZ16: 0.3005 | FA16: 0.3668 | FB16: 0.4882 | FC16: 0.086 | FD16: 0.2424 | FE16: 0.1113 | FF16: 0.2515 | FG16: 0.0142 | FH16: 0.2482 | FI16: 0.0079 | FJ16: 0.0872 | FK16: 0 | FL16: 0 | FM16: 0.0792 | FN16: 0 | FO16: 0 | FP16: 0.6052
A17: N1106 | B17: ADVW | C17: 326 | D17: ADVW.326.4 | G17: 1432.7978 | H17: 87.9623 | I17: 276.3416 | J17: 0.63865 | K17: 0.0132 | L17: 137.9676 | M17: 122.5248 | N17: 180.9776 | O17: 125.4455 | P17: 95.14 | Q17: 57.5843 | R17: 62.1727 | S17: 32.4983 | T17: 29.3895 | U17: 38.4482 | V17: 39.9031 | W17: 33.2372 | X17: 33.0835 | Y17: 31.6703 | Z17: 25.4185 | AA17: 26.1884 | AB17: 21.8387 | AC17: 15.0976 | AD17: 14.1428 | AE17: 13.2273 | AF17: 13.4095 | AG17: 14.177 | AH17: 18.6342 | AI17: 13.8779 | AJ17: 14.5551 | AK17: 17.6194 | AL17: 21.5923 | AM17: 23.3763 | AN17: 19.4957 | AO17: 20.0917 | AP17: 15.2659 | AQ17: 18.352 | AR17: 18.5165 | AS17: 16.9148 | AT17: 14.632 | AU17: 11.9654 | AV17: 7.51 | AW17: 3.0939 | AX17: 3.5474 | AY17: 2.5207 | AZ17: 2.561 | BA17: 0.923 | BB17: 0.8547 | BC17: 0.4767 | BD17: 0.454 | BE17: 0.5269 | BF17: 0.343 | BG17: 0.2851 | BH17: 0.0739 | BI17: 0 | BJ17: 0 | BK17: 0 | BL17: 0.0697 | BM17: 0 | BN17: 0 | BO17: 0.0967 | BP17: 0.0137 | BQ17: 0.067 | BR17: 0.0428 | BS17: 0 | BT17: 0 | BU17: 0 | BV17: 0 | BW17: 0 | BX17: 0 | BY17: 0 | BZ17: 0 | CA17: 0 | CB17: 0 | CC17: 0 | CD17: 0 | CE17: 0 | CF17: 0 | CG17: 0 | CH17: 0 | CI17: 0 | CJ17: 0 | CK17: 0 | CL17: 0 | CM17: 0 | CN17: 0.0002 | CO17: 3.5946 | CP17: 4.7748 | CQ17: 9.9437 | CR17: 8.7465 | CS17: 8.1632 | CT17: 5.88 | CU17: 7.3117 | CV17: 4.3386 | CW17: 4.3779 | CX17: 6.346 | CY17: 7.2363 | CZ17: 6.5092 | DA17: 7.0083 | DB17: 7.2066 | DC17: 6.1939 | DD17: 6.7782 | DE17: 5.9908 | DF17: 4.3861 | DG17: 4.3391 | DH17: 4.2621 | DI17: 4.5364 | DJ17: 5.0096 | DK17: 6.8802 | DL17: 5.3486 | DM17: 5.8172 | DN17: 7.327 | DO17: 9.3449 | DP17: 10.4588 | DQ17: 9.0232 | DR17: 9.6198 | DS17: 7.5579 | DT17: 9.3716 | DU17: 9.7343 | DV17: 9.1666 | DW17: 8.1594 | DX17: 6.8645 | DY17: 4.4214 | DZ17: 1.87 | EA17: 2.1992 | EB17: 1.6043 | EC17: 1.6702 | ED17: 0.6161 | EE17: 0.5834 | EF17: 0.3339 | EG17: 0.3243 | EH17: 0.3863 | EI17: 0.2554 | EJ17: 0.2174 | EK17: 0.0569 | EL17: 0 | EM17: 0 | EN17: 0 | EO17: 0.0588 | EP17: 0 | EQ17: 0 | ER17: 0.0856 | ES17: 0.0125 | ET17: 0.0619 | EU17: 0.0401 | EV17: 0 | EW17: 0 | EX17: 0 | EY17: 0 | EZ17: 0 | FA17: 0 | FB17: 0 | FC17: 0 | FD17: 0 | FE17: 0 | FF17: 0 | FG17: 0 | FH17: 0 | FI17: 0 | FJ17: 0 | FK17: 0 | FL17: 0 | FM17: 0 | FN17: 0 | FO17: 0 | FP17: 0
A18: N1107 | B18: VWAD | C18: 195 | D18: VWAD.195.4 | F18: =VLOOKUP(A18,[1]ROOT!$A$1:$C$1048576,3,0) -> #N/A | G18: 3568.3422 | H18: 239.3569 | I18: 751.9622 | J18: 0.68465 | K18: 0 | L18: 689.2497 | M18: 584.9755 | N18: 304.6522 | O18: 1.0178 | P18: 254.4023 | Q18: 99.1215 | R18: 152.7796 | S18: 71.5409 | T18: 13.2381 | U18: 65.7657 | V18: 64.2842 | W18: 37.4636 | X18: 54.8554 | Y18: 44.5093 | Z18: 35.5828 | AA18: 25.8183 | AB18: 53.3088 | AC18: 19.5097 | AD18: 58.4689 | AE18: 38.2414 | AF18: 69.8889 | AG18: 17.4656 | AH18: 50.3849 | AI18: 57.4397 | AJ18: 10.0486 | AK18: 76.0175 | AL18: 75.9694 | AM18: 35.2564 | AN18: 28.6496 | AO18: 78.6409 | AP18: 34.7549 | AQ18: 57.9263 | AR18: 40.247 | AS18: 28.6606 | AT18: 48.8504 | AU18: 32.744 | AV18: 5.054 | AW18: 20.8174 | AX18: 23.7059 | AY18: 8.5214 | AZ18: 9.2777 | BA18: 12.6906 | BB18: 9.7838 | BC18: 6.3787 | BD18: 6.2933 | BE18: 5.376 | BF18: 1.6518 | BG18: 6.7104 | BH18: 5.2293 | BI18: 0.9315 | BJ18: 4.1208 | BK18: 4.4339 | BL18: 3.0122 | BM18: 1.5192 | BN18: 3.1115 | BO18: 0.4744 | BP18: 2.5174 | BQ18: 1.6056 | BR18: 1.1737 | BS18: 2.2319 | BT18: 1.2755 | BU18: 0.1523 | BV18: 0.8202 | BW18: 1.5174 | BX18: 0.4542 | BY18: 0.3799 | BZ18: 0.4615 | CA18: 0.5496 | CB18: 0.146 | CC18: 0.3245 | CD18: 0.3327 | CE18: 0.1026 | CF18: 0.2914 | CG18: 0.0396 | CH18: 0 | CI18: 0.3605 | CJ18: 0.629 | CK18: 0.5013 | CL18: 0.009 | CM18: 0.6672 | CN18: 0 | CO18: 14.7262 | CP18: 24.7477 | CQ18: 18.6013 | CR18: 0.0704 | CS18: 21.202 | CT18: 10.0814 | CU18: 17.836 | CV18: 9.9308 | CW18: 1.9141 | CX18: 10.6991 | CY18: 11.7616 | CZ18: 7.4431 | DA18: 11.5071 | DB18: 10.1181 | DC18: 8.7383 | DD18: 6.5942 | DE18: 14.6032 | DF18: 5.6417 | DG18: 17.7802 | DH18: 12.3116 | DI18: 23.8471 | DJ18: 6.1965 | DK18: 18.6065 | DL18: 22.3916 | DM18: 3.9961 | DN18: 31.5968 | DO18: 33.1224 | DP18: 15.9937 | DQ18: 13.1869 | DR18: 37.6594 | DS18: 17.2538 | DT18: 29.5637 | DU18: 21.2442 | DV18: 15.3922 | DW18: 27.1316 | DX18: 18.8851 | DY18: 2.9946 | DZ18: 12.4668 | EA18: 14.7063 | EB18: 5.449 | EC18: 6.0238 | ED18: 8.4434 | EE18: 6.7051 | EF18: 4.4841 | EG18: 4.5046 | EH18: 3.9464 | EI18: 1.2283 | EJ18: 5.1072 | EK18: 4.0909 | EL18: 0.7415 | EM18: 3.321 | EN18: 3.6569 | EO18: 2.5477 | EP18: 1.2968 | EQ18: 2.7134 | ER18: 0.4213 | ES18: 2.2722 | ET18: 1.4785 | EU18: 1.0938 | EV18: 2.1126 | EW18: 1.2343 | EX18: 0.1501 | EY18: 0.8127 | EZ18: 1.5375 | FA18: 0.4697 | FB18: 0.3963 | FC18: 0.4871 | FD18: 0.5914 | FE18: 0.1599 | FF18: 0.3571 | FG18: 0.3739 | FH18: 0.1165 | FI18: 0.3361 | FJ18: 0.0466 | FK18: 0 | FL18: 0.4318 | FM18: 0.7666 | FN18: 0.6212 | FO18: 0.0112 | FP18: 0.8756
A19: N1108 | B19: ADVW | C19: 341 | D19: ADVW.341.4 | G19: 2836.5166 | H19: 224.4443 | I19: 705.1126 | J19: 0.7667 | K19: 0 | L19: 9.1309 | M19: 23.3795 | N19: 176.6801 | O19: 265.8885 | P19: 244.3117 | Q19: 379.5237 | R19: 193.4951 | S19: 164.1864 | T19: 135.9026 | U19: 166.7925 | V19: 59.7637 | W19: 95.0247 | X19: 51.5887 | Y19: 30.67 | Z19: 41.9859 | AA19: 48.256 | AB19: 43.3102 | AC19: 33.7183 | AD19: 38.0772 | AE19: 33.964 | AF19: 46.0386 | AG19: 18.8388 | AH19: 32.1772 | AI19: 39.3277 | AJ19: 21.982 | AK19: 36.6112 | AL19: 23.2751 | AM19: 26.6894 | AN19: 32.2086 | AO19: 33.1165 | AP19: 28.6571 | AQ19: 28.6995 | AR19: 32.9507 | AS19: 27.1902 | AT19: 30.1438 | AU19: 24.3269 | AV19: 11.4459 | AW19: 14.9623 | AX19: 18.1795 | AY19: 13.1754 | AZ19: 10.4581 | BA19: 7.5975 | BB19: 8.7827 | BC19: 8.7417 | BD19: 7.5272 | BE19: 2.6291 | BF19: 2.663 | BG19: 2.3858 | BH19: 3.4527 | BI19: 1.2597 | BJ19: 1.2229 | BK19: 0.4721 | BL19: 0.1972 | BM19: 0.4921 | BN19: 0.2475 | BO19: 0.1062 | BP19: 0.1925 | BQ19: 0.4061 | BR19: 0.0825 | BS19: 0.2776 | BT19: 0.2489 | BU19: 0.0539 | BV19: 0.0227 | BW19: 0 | BX19: 0.0063 | BY19: 0.1402 | BZ19: 0.0063 | CA19: 0.0063 | CB19: 0.0132 | CC19: 0 | CD19: 0 | CE19: 0 | CF19: 0 | CG19: 0 | CH19: 0 | CI19: 0 | CJ19: 0 | CK19: 0 | CL19: 0 | CM19: 0 | CN19: 0 | CO19: 0.2506 | CP19: 0.9316 | CQ19: 10.0664 | CR19: 18.9866 | CS19: 20.5318 | CT19: 38.1829 | CU19: 23.0268 | CV19: 21.884 | CW19: 19.9363 | CX19: 27.6894 | CY19: 10.8489 | CZ19: 18.6007 | DA19: 11.1338 | DB19: 6.9534 | DC19: 10.1467 | DD19: 12.47 | DE19: 11.9703 | DF19: 9.7958 | DG19: 11.6769 | DH19: 10.8777 | DI19: 15.6147 | DJ19: 6.7249 | DK19: 11.817 | DL19: 15.2069 | DM19: 8.7901 | DN19: 15.264 | DO19: 10.1005 | DP19: 11.8972 | DQ19: 14.908 | DR19: 15.9157 | DS19: 14.1387 | DT19: 14.6209 | DU19: 17.3456 | DV19: 14.687 | DW19: 16.7485 | DX19: 13.9759 | DY19: 6.7649 | DZ19: 9.0103 | EA19: 11.2876 | EB19: 8.4004 | EC19: 6.8361 | ED19: 5.0409 | EE19: 5.9837 | EF19: 6.1296 | EG19: 5.3945 | EH19: 1.9222 | EI19: 1.9769 | EJ19: 1.8102 | EK19: 2.6906 | EL19: 0.9961 | EM19: 0.987 | EN19: 0.3895 | EO19: 0.1663 | EP19: 0.4204 | EQ19: 0.2165 | ER19: 0.0942 | ES19: 0.1733 | ET19: 0.3715 | EU19: 0.077 | EV19: 0.264 | EW19: 0.2397 | EX19: 0.0526 | EY19: 0.0226 | EZ19: 0 | FA19: 0.0066 | FB19: 0.1457 | FC19: 0.0067 | FD19: 0.0068 | FE19: 0.0145 | FF19: 0 | FG19: 0 | FH19: 0 | FI19: 0 | FJ19: 0 | FK19: 0 | FL19: 0 | FM19: 0 | FN19: 0 | FO19: 0 | FP19: 0
A20: N1109 | B20: VWAD | C20: 74 | D20: VWAD.74.4 | F20: 6.1796 | G20: 4227.4407 | H20: 303.512 | I20: 953.5112 | J20: 0.67636667 | K20: 0 | L20: 417.6501 | M20: 548.6158 | N20: 413.5807 | O20: 0.5677 | P20: 405.4525 | Q20: 177.8207 | R20: 239.5526 | S20: 143.4042 | T20: 30.0475 | U20: 150.4879 | V20: 115.0662 | W20: 66.3746 | X20: 82.2972 | Y20: 51.9768 | Z20: 57.8966 | AA20: 33.5293 | AB20: 67.6852 | AC20: 29.3997 | AD20: 66.6973 | AE20: 37.6349 | AF20: 70.2034 | AG20: 33.9251 | AH20: 47.4581 | AI20: 59.2901 | AJ20: 18.8667 | AK20: 71.7561 | AL20: 70.2863 | AM20: 38.463 | AN20: 25.6684 | AO20: 54.0019 | AP20: 40.9459 | AQ20: 43.8252 | AR20: 29.3679 | AS20: 45.5843 | AT20: 62.9172 | AU20: 56.878 | AV20: 1.5013 | AW20: 52.532 | AX20: 50.6574 | AY20: 32.6167 | AZ20: 20.4067 | BA20: 14.3565 | BB20: 27.1874 | BC20: 22.32 | BD20: 12.8134 | BE20: 21.9683 | BF20: 6.9992 | BG20: 13.2146 | BH20: 9.8574 | BI20: 3.7965 | BJ20: 2.956 | BK20: 6.2526 | BL20: 5.548 | BM20: 1.9982 | BN20: 2.5976 | BO20: 0.697 | BP20: 2.2633 | BQ20: 1.2814 | BR20: 1.2386 | BS20: 0.688 | BT20: 0.2068 | BU20: 0.5282 | BV20: 0.1439 | BW20: 0.9282 | BX20: 0.0926 | BY20: 0.1058 | BZ20: 0.2407 | CA20: 0.1375 | CB20: 0.0064 | CC20: 0.0159 | CD20: 0.2443 | CE20: 0.0069 | CF20: 0.3353 | CG20: 0.0772 | CH20: 0.0206 | CI20: 0.0681 | CJ20: 0.0296 | CK20: 0.0201 | CL20: 0.0201 | CM20: 0.0449 | CN20: 0 | CO20: 8.9809 | CP20: 23.2919 | CQ20: 25.2614 | CR20: 0.0392 | CS20: 33.7664 | CT20: 18.0422 | CU20: 28.0489 | CV20: 19.916 | CW20: 4.3444 | CX20: 24.3801 | CY20: 21.0034 | CZ20: 13.1872 | DA20: 17.3486 | DB20: 11.8144 | DC20: 14.1865 | DD20: 8.6109 | DE20: 18.5343 | DF20: 8.5015 | DG20: 20.2873 | DH20: 12.0776 | DI20: 23.7607 | DJ20: 12.0445 | DK20: 17.5508 | DL20: 23.0744 | DM20: 7.5179 | DN20: 29.8044 | DO20: 30.6265 | DP20: 17.4674 | DQ20: 11.7964 | DR20: 25.7909 | DS20: 20.3371 | DT20: 22.5224 | DU20: 15.4047 | DV20: 24.5019 | DW20: 35.0413 | DX20: 32.8644 | DY20: 0.8896 | DZ20: 31.4536 | EA20: 31.3725 | EB20: 20.8462 | EC20: 13.367 | ED20: 9.5188 | EE20: 18.5159 | EF20: 15.631 | EG20: 9.1943 | EH20: 16.0769 | EI20: 5.2045 | EJ20: 10.0487 | EK20: 7.6986 | EL20: 3.0252 | EM20: 2.3817 | EN20: 5.1351 | EO20: 4.6722 | EP20: 1.7111 | EQ20: 2.2621 | ER20: 0.6191 | ES20: 2.0372 | ET20: 1.1769 | EU20: 1.1565 | EV20: 0.6524 | EW20: 0.2002 | EX20: 0.5188 | EY20: 0.1432 | EZ20: 0.9407 | FA20: 0.0957 | FB20: 0.1098 | FC20: 0.2544 | FD20: 0.1481 | FE20: 0.007 | FF20: 0.0175 | FG20: 0.273 | FH20: 0.0078 | FI20: 0.3871 | FJ20: 0.0908 | FK20: 0.0244 | FL20: 0.0817 | FM20: 0.036 | FN20: 0.0249 | FO20: 0.025 | FP20: 0.0567
A21: N1111 | B21: F0 | C21: VS16 | D21: F0.VS16 | G21: 5380.7057 | H21: 273.2422 | I21: 858.4157 | J21: 0.547725 | K21: 0.0127 | L21: 658.1154 | M21: 709.6122 | N21: 607.9467 | O21: 280.5529 | P21: 658.0558 | Q21: 365.1462 | R21: 283.197 | S21: 164.3805 | T21: 81.3846 | U21: 168.498 | V21: 104.0283 | W21: 96.234 | X21: 105.5116 | Y21: 79.8183 | Z21: 76.2825 | AA21: 67.7118 | AB21: 101.1873 | AC21: 52.2369 | AD21: 88.843 | AE21: 59.3657 | AF21: 94.1234 | AG21: 39.2758 | AH21: 61.0186 | AI21: 72.1518 | AJ21: 22.1807 | AK21: 56.7558 | AL21: 37.6854 | AM21: 33.2501 | AN21: 25.8585 | AO21: 32.3457 | AP21: 18.4862 | AQ21: 17.8941 | AR21: 10.4798 | AS21: 7.2437 | AT21: 7.3861 | AU21: 6.1678 | AV21: 2.9392 | AW21: 3.7921 | AX21: 4.4459 | AY21: 1.8119 | AZ21: 1.6821 | BA21: 1.9696 | BB21: 2.377 | BC21: 1.564 | BD21: 0.8057 | BE21: 1.1071 | BF21: 0.3911 | BG21: 0.7466 | BH21: 0.3926 | BI21: 0.3341 | BJ21: 0.2548 | BK21: 0.8843 | BL21: 0.1247 | BM21: 0.3468 | BN21: 0.1105 | BO21: 0 | BP21: 0 | BQ21: 0.0385 | BR21: 0.1009 | BS21: 0.1016 | BT21: 0.087 | BU21: 0.1295 | BV21: 0.0201 | BW21: 0.0407 | BX21: 0.0206 | BY21: 0.2662 | BZ21: 0.0248 | CA21: 0.0296 | CB21: 0 | CC21: 0.1359 | CD21: 0 | CE21: 0.064 | CF21: 0.0248 | CG21: 0 | CH21: 0 | CI21: 0.0227 | CJ21: 0 | CK21: 0 | CL21: 0 | CM21: 0.0333 | CN21: 0.0002 | CO21: 14.1819 | CP21: 29.9942 | CQ21: 36.4716 | CR21: 20.3115 | CS21: 55.3222 | CT21: 36.8678 | CU21: 33.2788 | CV21: 22.4089 | CW21: 11.9071 | CX21: 27.6422 | CY21: 18.9916 | CZ21: 18.9513 | DA21: 22.4132 | DB21: 18.1422 | DC21: 18.6125 | DD21: 17.4273 | DE21: 27.7455 | DF21: 15.1361 | DG21: 27.1052 | DH21: 19.0453 | DI21: 31.9186 | DJ21: 13.9672 | DK21: 22.4841 | DL21: 27.988 | DM21: 8.8593 | DN21: 23.5834 | DO21: 16.374 | DP21: 14.9123 | DQ21: 11.9474 | DR21: 15.5197 | DS21: 9.1535 | DT21: 9.1268 | DU21: 5.5083 | DV21: 3.9009 | DW21: 4.1097 | DX21: 3.5532 | DY21: 1.7344 | DZ21: 2.2781 | EA21: 2.7641 | EB21: 1.1556 | EC21: 1.098 | ED21: 1.309 | EE21: 1.6194 | EF21: 1.0957 | EG21: 0.5789 | EH21: 0.809 | EI21: 0.2913 | EJ21: 0.5692 | EK21: 0.3061 | EL21: 0.2647 | EM21: 0.2057 | EN21: 0.7313 | EO21: 0.1049 | EP21: 0.2968 | EQ21: 0.0967 | ER21: 0 | ES21: 0 | ET21: 0.0439 | EU21: 0.0947 | EV21: 0.096 | EW21: 0.187 | EX21: 0.1262 | EY21: 0.0202 | EZ21: 0.0414 | FA21: 0.0211 | FB21: 0.2975 | FC21: 0.0263 | FD21: 0.0319 | FE21: 0 | FF21: 0.1514 | FG21: 0 | FH21: 0.0727 | FI21: 0.0287 | FJ21: 0 | FK21: 0 | FL21: 0.0273 | FM21: 0 | FN21: 0 | FO21: 0 | FP21: 0.045
A22: N1112 | B22: ADVW | C22: 258 | D22: ADVW.258.4 | G22: 6157.8174 | H22: 484.4884 | I22: 1522.0648 | J22: 0.76441667 | K22: 0.0195 | L22: 14.3641 | M22: 43.6216 | N22: 500.7626 | O22: 760.5999 | P22: 630.4583 | Q22: 835.5656 | R22: 382.6634 | S22: 282.0185 | T22: 213.0844 | U22: 259.3478 | V22: 105.1643 | W22: 153.5467 | X22: 93.2863 | Y22: 57.3337 | Z22: 70.5229 | AA22: 91.5585 | AB22: 87.5956 | AC22: 63.3509 | AD22: 88.4239 | AE22: 58.7592 | AF22: 90.6171 | AG22: 34.5444 | AH22: 64.8222 | AI22: 89.7126 | AJ22: 51.4553 | AK22: 91.2044 | AL22: 48.8765 | AM22: 66.4013 | AN22: 82.7686 | AO22: 76.3223 | AP22: 60.917 | AQ22: 82.3408 | AR22: 69.8572 | AS22: 52.6171 | AT22: 73.8735 | AU22: 59.3473 | AV22: 34.2861 | AW22: 31.5153 | AX22: 43.2657 | AY22: 23.5467 | AZ22: 28.0363 | BA22: 12.6098 | BB22: 20.2206 | BC22: 10.3283 | BD22: 8.5921 | BE22: 9.0866 | BF22: 5.0512 | BG22: 5.8058 | BH22: 5.2119 | BI22: 3.9964 | BJ22: 4.4541 | BK22: 4.1927 | BL22: 1.1626 | BM22: 1.1472 | BN22: 2.4355 | BO22: 1.6657 | BP22: 1.23 | BQ22: 1.9774 | BR22: 0.7076 | BS22: 0.9046 | BT22: 0.6398 | BU22: 0.6719 | BV22: 0.6281 | BW22: 0.7667 | BX22: 0.2846 | BY22: 0.6958 | BZ22: 0.4238 | CA22: 0.2685 | CB22: 0.6302 | CC22: 0.5135 | CD22: 1.0316 | CE22: 0.0486 | CF22: 0.0407 | CG22: 0 | CH22: 0 | CI22: 0.1083 | CJ22: 0 | CK22: 0.073 | CL22: 0.2065 | CM22: 0.8281 | CN22: 0.0003 | CO22: 0.3961 | CP22: 1.7855 | CQ22: 28.6443 | CR22: 53.9473 | CS22: 52.677 | CT22: 84.0435 | CU22: 45.4863 | CV22: 37.5465 | CW22: 31.2811 | CX22: 43.0554 | CY22: 19.0769 | CZ22: 30.0482 | DA22: 20.1514 | DB22: 12.994 | DC22: 17.0794 | DD22: 23.6708 | DE22: 24.1752 | DF22: 18.3825 | DG22: 27.1746 | DH22: 18.8367 | DI22: 30.7493 | DJ22: 12.315 | DK22: 23.784 | DL22: 34.7063 | DM22: 20.61 | DN22: 38.0274 | DO22: 21.1992 | DP22: 29.5792 | DQ22: 38.3353 | DR22: 36.766 | DS22: 29.9877 | DT22: 41.9424 | DU22: 36.8336 | DV22: 28.4138 | DW22: 41.0064 | DX22: 34.0597 | DY22: 20.2579 | DZ22: 18.9608 | EA22: 26.8668 | EB22: 15.0029 | EC22: 18.3033 | ED22: 8.3855 | EE22: 13.7696 | EF22: 7.2481 | EG22: 6.1514 | EH22: 6.6294 | EI22: 3.7634 | EJ22: 4.4076 | EK22: 4.0624 | EL22: 3.163 | EM22: 3.5997 | EN22: 3.4583 | EO22: 0.9754 | EP22: 0.9797 | EQ22: 2.1187 | ER22: 1.4789 | ES22: 1.1098 | ET22: 1.8131 | EU22: 0.6613 | EV22: 0.86 | EW22: 0.6178 | EX22: 0.6581 | EY22: 0.627 | EZ22: 0.7777 | FA22: 0.2918 | FB22: 0.7262 | FC22: 0.449 | FD22: 0.2887 | FE22: 0.6904 | FF22: 0.5673 | FG22: 1.1641 | FH22: 0.0553 | FI22: 0.047 | FJ22: 0 | FK22: 0 | FL22: 0.1294 | FM22: 0 | FN22: 0.0904 | FO22: 0.2571 | FP22: 1.232
A23: N1114 | B23: ADVW | C23: 271 | D23: ADVW.271.4 | F23: =VLOOKUP(A23,[1]ROOT!$A$1:$C$1048576,3,0) -> #N/A | G23: 2420.6118 | H23: 132.5038 | I23: 416.2732 | J23: 0.53305 | K23: 0 | L23: 395.7667 | M23: 400.6855 | N23: 257.7694 | O23: 0.6585 | P23: 257.1343 | Q23: 102.3967 | R23: 142.0384 | S23: 77.9466 | T23: 13.231 | U23: 77.1068 | V23: 58.9485 | W23: 31.5308 | X23: 43.6604 | Y23: 36.7312 | Z23: 29.8877 | AA23: 19.1796 | AB23: 32.5078 | AC23: 13.904 | AD23: 34.6316 | AE23: 21.7311 | AF23: 32.6472 | AG23: 8.1362 | AH23: 24.2418 | AI23: 23.6505 | AJ23: 5.4281 | AK23: 28.9994 | AL23: 30.4244 | AM23: 14.2594 | AN23: 17.2206 | AO23: 27.0838 | AP23: 10.1147 | AQ23: 17.0259 | AR23: 12.6563 | AS23: 12.6778 | AT23: 25.2974 | AU23: 14.8903 | AV23: 2.1972 | AW23: 10.4415 | AX23: 8.5934 | AY23: 5.0089 | AZ23: 4.5954 | BA23: 7.0724 | BB23: 5.5846 | BC23: 3.3116 | BD23: 1.5301 | BE23: 4.0323 | BF23: 0.5969 | BG23: 2.4555 | BH23: 1.3913 | BI23: 0.4034 | BJ23: 1.2577 | BK23: 1.5848 | BL23: 1.0642 | BM23: 0.7401 | BN23: 0.5785 | BO23: 0.0127 | BP23: 0.2565 | BQ23: 0.4511 | BR23: 0.689 | BS23: 0.8722 | BT23: 0.2696 | BU23: 0.1464 | BV23: 0.0069 | BW23: 0 | BX23: 0 | BY23: 0 | BZ23: 0 | CA23: 0 | CB23: 0 | CC23: 0.0635 | CD23: 0.4148 | CE23: 0.4214 | CF23: 0 | CG23: 0 | CH23: 0.1296 | CI23: 0 | CJ23: 0.0069 | CK23: 0 | CL23: 0 | CM23: 0.1698 | CN23: 0 | CO23: 8.4722 | CP23: 17.0483 | CQ23: 15.7465 | CR23: 0.0455 | CS23: 21.4702 | CT23: 10.4159 | CU23: 16.5931 | CV23: 10.8159 | CW23: 1.9131 | CX23: 12.5576 | CY23: 10.8084 | CZ23: 6.2536 | DA23: 9.1591 | DB23: 8.3525 | DC23: 7.3394 | DD23: 4.8952 | DE23: 8.9023 | DF23: 4.0208 | DG23: 10.5352 | DH23: 6.9941 | DI23: 11.119 | DJ23: 2.8797 | DK23: 8.9437 | DL23: 9.2217 | DM23: 2.1585 | DN23: 12.0589 | DO23: 13.2727 | DP23: 6.4684 | DQ23: 7.9252 | DR23: 12.9725 | DS23: 5.0204 | DT23: 8.7034 | DU23: 6.6898 | DV23: 6.8092 | DW23: 14.0634 | DX23: 8.595 | DY23: 1.3019 | DZ23: 6.2529 | EA23: 5.3299 | EB23: 3.2048 | EC23: 2.9794 | ED23: 4.6965 | EE23: 3.8119 | EF23: 2.3256 | EG23: 1.0953 | EH23: 2.9668 | EI23: 0.4438 | EJ23: 1.8683 | EK23: 1.0891 | EL23: 0.3218 | EM23: 1.0134 | EN23: 1.3055 | EO23: 0.8971 | EP23: 0.6333 | EQ23: 0.5054 | ER23: 0.0113 | ES23: 0.2327 | ET23: 0.4154 | EU23: 0.642 | EV23: 0.8305 | EW23: 0.2603 | EX23: 0.1446 | EY23: 0.0068 | EZ23: 0 | FA23: 0 | FB23: 0 | FC23: 0 | FD23: 0 | FE23: 0 | FF23: 0.0843 | FG23: 0.4671 | FH23: 0.4787 | FI23: 0 | FJ23: 0 | FK23: 0.1535 | FL23: 0 | FM23: 0.0083 | FN23: 0 | FO23: 0 | FP23: 0.2301
